<?xml version="1.0" ?>
<!-- =================================================================================== -->
<!-- |    This document was autogenerated by xacro from urdf/tracked.xacro               | -->
<!-- |    EDITING THIS FILE BY HAND IS NOT RECOMMENDED                                 | -->
<!-- =================================================================================== -->
<robot name="gvr_bot" xmlns:xacro="http://www.ros.org/wiki/xacro">
  <!-- <xacro:include filename="$(find pexod_description)/urdf/pexod_control.xacro" /> -->
  <!-- MATERIALS -->
  <material name="Blue">
    <color rgba="0 0 1 1"/>
  </material>
  <material name="Red">
    <color rgba="1 0 0 1"/>
  </material>
  <material name="Green">
    <color rgba="0 1 0 1"/>
  </material>
  <material name="Yellow">
    <color rgba="1 1 0 1"/>
  </material>
  <material name="Orange">
    <color rgba="1 0.5 0 1"/>
  </material>
  <material name="LightGrey">
    <color rgba="0.6 0.6 0.6 1.0"/>
  </material>
  <!-- END OF MATERIALS -->
  <!-- XACRO MACROS FOR VISUALS AND COLLISIONS -->
  <!-- END OF XACRO MACROS -->


  <!-- TORSO -->
  <link name="base_link">
    <visual>
      <origin rpy="0 0 0" xyz="0 0 0"/>
      <geometry>
        <mesh filename="./Base_Centered_Stripped.obj" scale="1.0 1.0 1.0" />
        <!-- <box size="0.3 0.2 0.1"/> -->
      </geometry>
      <!-- <material name="Blue"/> -->
    </visual>

    <collision>
      <origin rpy="0 0 0" xyz="0 0 0"/>
      <geometry>
        <box size="0.508 0.255 0.133"/>
      </geometry>
    </collision>
    <inertial>
      <!-- CENTER OF MASS -->
      <origin rpy="0 0 0" xyz="0 0 0"/>
      <mass value="11"/>
      <!-- <mass value="1.031"/> -->
      <!-- box inertia: 1/12*m(y^2+z^2), ... -->
      <!-- From the CAD File , See Notes Maxime -->
      <!-- <inertia ixx="0.255" ixy="-0.011" ixz="-0.001" iyx="-0.011" iyy="0.464" iyz="-0.002" izx="-0.001" izy="-0.002" izz="0.555"/> -->
      <inertia ixx="0.255" ixy="0" ixz="0" iyy="0.464" iyz="0" izz="0.555"/>
      <!-- <inertia ixx="0.0173333" ixy="0" ixz="0" iyy="0.02466667" iyz="0" izz="0.04066667"/> -->
    </inertial>
  </link>

  <!-- LINKS/JOINTS -->
  <joint name="body_track_left_front" type="fixed">
    <parent link="base_link"/>
    <child link="track_left_front"/>
    <origin rpy="0 0 0" xyz="-0.254 -0.1655 0"/>
    <dynamics damping="0.0"/>
  </joint>

  <link name="track_left_front">
    <!-- <visual>
      <origin rpy="1.5708 0 0" xyz="0 0 0"/> 
      <geometry>
        <cylinder length="0.05" radius="0.033"/>
      </geometry>
      <material name="Orange"/>
    </visual> -->

    <collision>
      <origin rpy="1.5708 0 0" xyz="0 0 0"/> 
      <geometry>
        <cylinder length="0.076" radius="0.082"/>
      </geometry>
    </collision>

    <inertial>
      <origin rpy="1.5708 0 0" xyz="0.0 0.0 0.0"/>
      <mass value="0.1"/>
      <inertia ixx="0.000497" ixy="0" ixz="0" iyy="0.000497" iyz="0" izz="0.000578"/>
    </inertial>
  </link>

  <!-- WHEELS -->

  <joint name="body_track_left_wheel_01" type="continuous">
    <parent link="base_link"/>
    <child link="track_left_wheel_01"/>
    <limit effort="30.0" lower="-1.57079632679" upper="1.57079632679" velocity="30.0"/>
    <origin rpy="0 0 0" xyz="-0.254 -0.1655 0"/>
    <axis xyz="0 1 0"/>
    <dynamics damping="0.0"/>
  </joint>

  <link name="track_left_wheel_01">
    <!-- <visual>
      <origin rpy="1.5708 0 0" xyz="0 0 0"/> 
      <geometry>
        <cylinder length="0.05" radius="0.06"/>
      </geometry>
      <material name="Orange"/>
    </visual> -->

    <collision>
      <origin rpy="1.5708 0 0" xyz="0 0 0"/> 
      <geometry>
        <cylinder length="0.076" radius="0.082"/>
      </geometry>
    </collision>

    <inertial>
      <origin rpy="1.5708 0 0" xyz="0.0 0.0 0.0"/>
      <!-- <mass value="1.49"/> -->
      <mass value="1.49"/>
      <inertia ixx= "0.046" ixy = "0.0" ixz = "0.0" iyy = "0.10" iyz = "0.0" izz = "0.141"/>
      <!-- <inertia ixx="0.000497" ixy="0" ixz="0" iyy="0.000497" iyz="0" izz="0.000578"/> -->
    </inertial>
  </link>

  <joint name="body_track_left_wheel_02" type="continuous">
    <parent link="base_link"/>
    <child link="track_left_wheel_02"/>
    <limit effort="30.0" lower="-1.57079632679" upper="1.57079632679" velocity="30.0"/>
    <origin rpy="0 0 0" xyz="-0.204 -0.1655 0"/>
    <axis xyz="0 1 0"/>
    <dynamics damping="0.0"/>
  </joint>

  <link name="track_left_wheel_02">
    <!-- <visual>
      <origin rpy="1.5708 0 0" xyz="0 0 0"/> 
      <geometry>
        <cylinder length="0.05" radius="0.06"/>
      </geometry>
      <material name="Orange"/>
    </visual> -->

    <collision>
      <origin rpy="1.5708 0 0" xyz="0 0 0"/> 
      <geometry>
        <cylinder length="0.076" radius="0.082"/>
      </geometry>
    </collision>

    <inertial>
      <origin rpy="1.5708 0 0" xyz="0.0 0.0 0.0"/>
      <mass value="1.49"/>
      <inertia ixx= "0.046" ixy = "0.0" ixz = "0.0" iyy = "0.10" iyz = "0.0" izz = "0.141"/>
      <!-- <inertia ixx="0.000497" ixy="0" ixz="0" iyy="0.000497" iyz="0" izz="0.000578"/> -->
    </inertial>
  </link>

  <joint name="body_track_left_wheel_03" type="continuous">
    <parent link="base_link"/>
    <child link="track_left_wheel_03"/>
    <limit effort="30.0" lower="-1.57079632679" upper="1.57079632679" velocity="30.0"/>
    <origin rpy="0 0 0" xyz="-0.154 -0.1655 0"/>
    <axis xyz="0 1 0"/>
    <dynamics damping="0.0"/>
  </joint>

  <link name="track_left_wheel_03">
    <!-- <visual>
      <origin rpy="1.5708 0 0" xyz="0 0 0"/> 
      <geometry>
        <cylinder length="0.05" radius="0.06"/>
      </geometry>
      <material name="Orange"/>
    </visual> -->

    <collision>
      <origin rpy="1.5708 0 0" xyz="0 0 0"/> 
      <geometry>
        <cylinder length="0.076" radius="0.082"/>
      </geometry>
    </collision>

    <inertial>
      <origin rpy="1.5708 0 0" xyz="0.0 0.0 0.0"/>
      <mass value="1.49"/>
      <inertia ixx= "0.046" ixy = "0.0" ixz = "0.0" iyy = "0.10" iyz = "0.0" izz = "0.141"/>
      <!-- <inertia ixx="0.000497" ixy="0" ixz="0" iyy="0.000497" iyz="0" izz="0.000578"/> -->
    </inertial>
  </link>

  <joint name="body_track_left_wheel_04" type="continuous">
    <parent link="base_link"/>
    <child link="track_left_wheel_04"/>
    <limit effort="30.0" lower="-1.57079632679" upper="1.57079632679" velocity="30.0"/>
    <origin rpy="0 0 0" xyz="-0.104 -0.1655 0"/>
    <axis xyz="0 1 0"/>
    <dynamics damping="0.0"/>
  </joint>

  <link name="track_left_wheel_04">
    <!-- <visual>
      <origin rpy="1.5708 0 0" xyz="0 0 0"/> 
      <geometry>
        <cylinder length="0.05" radius="0.06"/>
      </geometry>
      <material name="Orange"/>
    </visual> -->

    <collision>
      <origin rpy="1.5708 0 0" xyz="0 0 0"/> 
      <geometry>
        <cylinder length="0.076" radius="0.082"/>
      </geometry>
    </collision>

    <inertial>
      <origin rpy="1.5708 0 0" xyz="0.0 0.0 0.0"/>
      <mass value="1.49"/>
      <inertia ixx= "0.046" ixy = "0.0" ixz = "0.0" iyy = "0.10" iyz = "0.0" izz = "0.141"/>
      <!-- <inertia ixx="0.000497" ixy="0" ixz="0" iyy="0.000497" iyz="0" izz="0.000578"/> -->
    </inertial>
  </link>

  <joint name="body_track_left_wheel_05" type="continuous">
    <parent link="base_link"/>
    <child link="track_left_wheel_05"/>
    <limit effort="30.0" lower="-1.57079632679" upper="1.57079632679" velocity="30.0"/>
    <origin rpy="0 0 0" xyz="-0.054 -0.1655 0"/>
    <axis xyz="0 1 0"/>
    <dynamics damping="0.0"/>
  </joint>

  <link name="track_left_wheel_05">
    <!-- <visual>
      <origin rpy="1.5708 0 0" xyz="0 0 0"/> 
      <geometry>
        <cylinder length="0.05" radius="0.06"/>
      </geometry>
      <material name="Orange"/>
    </visual> -->

    <collision>
      <origin rpy="1.5708 0 0" xyz="0 0 0"/> 
      <geometry>
        <cylinder length="0.076" radius="0.082"/>
      </geometry>
    </collision>

    <inertial>
      <origin rpy="1.5708 0 0" xyz="0.0 0.0 0.0"/>
      <mass value="1.49"/>
      <inertia ixx= "0.046" ixy = "0.0" ixz = "0.0" iyy = "0.10" iyz = "0.0" izz = "0.141"/>
      <!-- <inertia ixx="0.000497" ixy="0" ixz="0" iyy="0.000497" iyz="0" izz="0.000578"/> -->
    </inertial>
  </link>

  <joint name="body_track_left_wheel_06" type="continuous">
    <parent link="base_link"/>
    <child link="track_left_wheel_06"/>
    <limit effort="30.0" lower="-1.57079632679" upper="1.57079632679" velocity="30.0"/>
    <origin rpy="0 0 0" xyz="0.0 -0.1655 0"/>
    <axis xyz="0 1 0"/>
    <dynamics damping="0.0"/>
  </joint>

  <link name="track_left_wheel_06">
    <!-- <visual>
      <origin rpy="1.5708 0 0" xyz="0 0 0"/> 
      <geometry>
        <cylinder length="0.05" radius="0.06"/>
      </geometry>
      <material name="Orange"/>
    </visual> -->

    <collision>
      <origin rpy="1.5708 0 0" xyz="0 0 0"/> 
      <geometry>
        <cylinder length="0.076" radius="0.082"/>
      </geometry>
    </collision>

    <inertial>
      <origin rpy="1.5708 0 0" xyz="0.0 0.0 0.0"/>
      <mass value="1.49"/>
      <inertia ixx= "0.046" ixy = "0.0" ixz = "0.0" iyy = "0.10" iyz = "0.0" izz = "0.141"/>
      <!-- <inertia ixx="0.000497" ixy="0" ixz="0" iyy="0.000497" iyz="0" izz="0.000578"/> -->
    </inertial>
  </link>

  <joint name="body_track_left_wheel_07" type="continuous">
    <parent link="base_link"/>
    <child link="track_left_wheel_07"/>
    <limit effort="30.0" lower="-1.57079632679" upper="1.57079632679" velocity="30.0"/>
    <origin rpy="0 0 0" xyz="0.054 -0.1655 0"/>
    <axis xyz="0 1 0"/>
    <dynamics damping="0.0"/>
  </joint>

  <link name="track_left_wheel_07">
    <!-- <visual>
      <origin rpy="1.5708 0 0" xyz="0 0 0"/> 
      <geometry>
        <cylinder length="0.05" radius="0.06"/>
      </geometry>
      <material name="Orange"/>
    </visual> -->

    <collision>
      <origin rpy="1.5708 0 0" xyz="0 0 0"/> 
      <geometry>
        <cylinder length="0.076" radius="0.082"/>
      </geometry>
    </collision>

    <inertial>
      <origin rpy="1.5708 0 0" xyz="0.0 0.0 0.0"/>
      <mass value="1.49"/>
      <inertia ixx= "0.046" ixy = "0.0" ixz = "0.0" iyy = "0.10" iyz = "0.0" izz = "0.141"/>
      <!-- <inertia ixx="0.000497" ixy="0" ixz="0" iyy="0.000497" iyz="0" izz="0.000578"/> -->
    </inertial>
  </link>

  <joint name="body_track_left_wheel_08" type="continuous">
    <parent link="base_link"/>
    <child link="track_left_wheel_08"/>
    <limit effort="30.0" lower="-1.57079632679" upper="1.57079632679" velocity="30.0"/>
    <origin rpy="0 0 0" xyz="0.104 -0.1655 0"/>
    <axis xyz="0 1 0"/>
    <dynamics damping="0.0"/>
  </joint>

  <link name="track_left_wheel_08">
    <!-- <visual>
      <origin rpy="1.5708 0 0" xyz="0 0 0"/> 
      <geometry>
        <cylinder length="0.05" radius="0.06"/>
      </geometry>
      <material name="Orange"/>
    </visual> -->

    <collision>
      <origin rpy="1.5708 0 0" xyz="0 0 0"/> 
      <geometry>
        <cylinder length="0.076" radius="0.082"/>
      </geometry>
    </collision>

    <inertial>
      <origin rpy="1.5708 0 0" xyz="0.0 0.0 0.0"/>
      <mass value="1.49"/>
      <inertia ixx= "0.046" ixy = "0.0" ixz = "0.0" iyy = "0.10" iyz = "0.0" izz = "0.141"/>
      <!-- <inertia ixx="0.000497" ixy="0" ixz="0" iyy="0.000497" iyz="0" izz="0.000578"/> -->
    </inertial>
  </link>

  <joint name="body_track_left_wheel_09" type="continuous">
    <parent link="base_link"/>
    <child link="track_left_wheel_09"/>
    <limit effort="30.0" lower="-1.57079632679" upper="1.57079632679" velocity="30.0"/>
    <origin rpy="0 0 0" xyz="0.154 -0.1655 0"/>
    <axis xyz="0 1 0"/>
    <dynamics damping="0.0"/>
  </joint>

  <link name="track_left_wheel_09">
    <!-- <visual>
      <origin rpy="1.5708 0 0" xyz="0 0 0"/> 
      <geometry>
        <cylinder length="0.05" radius="0.06"/>
      </geometry>
      <material name="Orange"/>
    </visual> -->

    <collision>
      <origin rpy="1.5708 0 0" xyz="0 0 0"/> 
      <geometry>
        <cylinder length="0.076" radius="0.082"/>
      </geometry>
    </collision>

    <inertial>
      <origin rpy="1.5708 0 0" xyz="0.0 0.0 0.0"/>
      <mass value="1.49"/>
      <inertia ixx= "0.046" ixy = "0.0" ixz = "0.0" iyy = "0.10" iyz = "0.0" izz = "0.141"/>
      <!-- <inertia ixx="0.000497" ixy="0" ixz="0" iyy="0.000497" iyz="0" izz="0.000578"/> -->
    </inertial>
  </link>

  <joint name="body_track_left_wheel_10" type="continuous">
    <parent link="base_link"/>
    <child link="track_left_wheel_10"/>
    <limit effort="30.0" lower="-1.57079632679" upper="1.57079632679" velocity="30.0"/>
    <origin rpy="0 0 0" xyz="0.204 -0.1655 0"/>
    <axis xyz="0 1 0"/>
    <dynamics damping="0.0"/>
  </joint>

  <link name="track_left_wheel_10">
    <!-- <visual>
      <origin rpy="1.5708 0 0" xyz="0 0 0"/> 
      <geometry>
        <cylinder length="0.05" radius="0.06"/>
      </geometry>
      <material name="Orange"/>
    </visual> -->

    <collision>
      <origin rpy="1.5708 0 0" xyz="0 0 0"/> 
      <geometry>
        <cylinder length="0.076" radius="0.082"/>
      </geometry>
    </collision>

    <inertial>
      <origin rpy="1.5708 0 0" xyz="0.0 0.0 0.0"/>
      <mass value="1.49"/>
      <inertia ixx= "0.046" ixy = "0.0" ixz = "0.0" iyy = "0.10" iyz = "0.0" izz = "0.141"/>
      <!-- <inertia ixx="0.000497" ixy="0" ixz="0" iyy="0.000497" iyz="0" izz="0.000578"/> -->
    </inertial>
  </link>

  <joint name="body_track_left_wheel_11" type="continuous">
    <parent link="base_link"/>
    <child link="track_left_wheel_11"/>
    <limit effort="30.0" lower="-1.57079632679" upper="1.57079632679" velocity="30.0"/>
    <origin rpy="0 0 0" xyz="0.254 -0.1655 0"/>
    <axis xyz="0 1 0"/>
    <dynamics damping="0.0"/>
  </joint>

  <link name="track_left_wheel_11">
    <!-- <visual>
      <origin rpy="1.5708 0 0" xyz="0 0 0"/> 
      <geometry>
        <cylinder length="0.05" radius="0.06"/>
      </geometry>
      <material name="Orange"/>
    </visual> -->

    <collision>
      <origin rpy="1.5708 0 0" xyz="0 0 0"/> 
      <geometry>
        <cylinder length="0.076" radius="0.082"/>
      </geometry>
    </collision>

    <inertial>
      <origin rpy="1.5708 0 0" xyz="0.0 0.0 0.0"/>
      <mass value="1.49"/>
      <inertia ixx= "0.046" ixy = "0.0" ixz = "0.0" iyy = "0.10" iyz = "0.0" izz = "0.141"/>
      <!-- <inertia ixx="0.000497" ixy="0" ixz="0" iyy="0.000497" iyz="0" izz="0.000578"/> -->
    </inertial>
  </link>

  <joint name="body_track_left_flipper" type="revolute">
    <parent link="track_left_front"/>
    <child link="track_left_flipper"/>
    <limit effort="30.0" lower="-1.57079632679" upper="1.57079632679" velocity="7.0"/>
    <origin rpy="0 3.14 0" xyz="0 -0.05 0"/>
    <axis xyz="0 1 0"/>
    <dynamics damping="0.0"/>
  </joint>

  <link name="track_left_flipper">
    <!-- <visual>
      <origin rpy="0 0 0" xyz="0.07 0. 0."/> 
      <geometry>
        <box size="0.15 0.05 0.05"/>
      </geometry>
      <material name="Red"/>
    </visual> -->

    <collision>
      <origin rpy="0 0 0" xyz="0.07 0. 0."/> 
      <geometry>
        <box size="0.15 0.05 0.05"/>
      </geometry>
    </collision>

    <inertial>
      <!-- CENTER OF MASS -->
      <origin rpy="0 0 0" xyz="0.07 0. 0."/> 
      <mass value=".5"/>
      <!-- box inertia: 1/12*m(y^2+z^2), ... -->
      <inertia ixx="0.00020833" ixy="0" ixz="0" iyy="0.001770833" iyz="0" izz="0.001770833"/>
    </inertial>
  </link>


  <joint name="body_track_left_flipper_end" type="fixed">
    <parent link="track_left_flipper"/>
    <child link="track_left_flipper_end"/>
  </joint>

  <link name="track_left_flipper_end">
    <!-- <visual>
      <origin rpy="1.5708 0 0" xyz="0.14 0. 0."/> 
      <geometry>
        <cylinder length="0.05" radius="0.023"/>
      </geometry>
      <material name="Orange"/>
    </visual> -->

    <collision>
      <origin rpy="1.5708 0 0" xyz="0.14 0. 0."/> 
      <geometry>
        <cylinder length="0.05" radius="0.023"/>
      </geometry>
    </collision>

    <inertial>
      <origin rpy="1.5708 0 0" xyz="0.14 0. 0."/> 
      <mass value=".1"/>
      <inertia ixx="0.0000497" ixy="0" ixz="0" iyy="0.0000497" iyz="0" izz="0.0000578"/>
    </inertial>
  </link>

  <joint name="body_track_left_back" type="fixed">
    <parent link="base_link"/>
    <child link="track_left_back"/>
    <origin rpy="0 0 0" xyz="0.254 -0.1655 0"/>
    <axis xyz="0 1 0"/>
    <dynamics damping="0.0"/>
  </joint>

  <link name="track_left_back">
    <!-- <visual>
      <origin rpy="1.5708 0 0" xyz="0 0 0"/> 
      <geometry>
        <cylinder length="0.05" radius="0.033"/>
      </geometry>
      <material name="Orange"/>
    </visual> -->

    <collision>
      <origin rpy="1.5708 0 0" xyz="0 0 0"/> 
      <geometry>
        <cylinder length="0.076" radius="0.082"/>
      </geometry>
    </collision>

    <inertial>
      <origin rpy="1.5708 0 0" xyz="0 0 0"/> 
      <mass value="0.1"/>
      <inertia ixx="0.000497" ixy="0" ixz="0" iyy="0.000497" iyz="0" izz="0.000578"/>
    </inertial>
  </link>

  <!-- RIGHT TRACK -->  
  <joint name="body_track_right_front" type="fixed">
    <parent link="base_link"/>
    <child link="track_right_front"/>
    <origin rpy="0 0 0" xyz="-0.254 0.1655 0"/>
    <dynamics damping="0.0"/>
  </joint>

  <link name="track_right_front">
    <!-- <visual>
      <origin rpy="1.5708 0 0" xyz="0 0 0"/> 
      <geometry>
        <cylinder length="0.05" radius="0.033"/>
      </geometry>
      <material name="Orange"/>
    </visual> -->

    <collision>
      <origin rpy="1.5708 0 0" xyz="0 0 0"/> 
      <geometry>
        <cylinder length="0.076" radius="0.082"/>
      </geometry>
    </collision>

    <inertial>
      <origin rpy="1.5708 0 0" xyz="0 0 0"/> 
      <mass value="0.1"/>
      <inertia ixx="0.000497" ixy="0" ixz="0" iyy="0.000497" iyz="0" izz="0.000578"/>
    </inertial>
  </link>

  <joint name="body_track_right_flipper" type="revolute">
    <parent link="track_right_front"/>
    <child link="track_right_flipper"/>
    <limit effort="30.0" lower="-1.57079632679" upper="1.57079632679" velocity="7.0"/>
    <origin rpy="0 3.14 0" xyz="0 0.05 0"/>
    <axis xyz="0 1 0"/>
    <dynamics damping="0.0"/>
  </joint>

  <link name="track_right_flipper">
    <!-- <visual>
      <origin rpy="0 0 0" xyz="0.07 0. 0."/> 
      <geometry>
        <box size="0.15 0.05 0.05"/>
      </geometry>
      <material name="Red"/>
    </visual> -->

    <collision>
      <origin rpy="0 0 0" xyz="0.07 0. 0."/> 
      <geometry>
        <box size="0.15 0.05 0.05"/>
      </geometry>
    </collision>

    <inertial>
      <!-- CENTER OF MASS -->
      <origin rpy="0 0 0" xyz="0.07 0. 0."/> 
      <mass value=".5"/>
      <!-- box inertia: 1/12*m(y^2+z^2), ... -->
      <inertia ixx="0.00020833" ixy="0" ixz="0" iyy="0.001770833" iyz="0" izz="0.001770833"/>
    </inertial>
  </link>

  <joint name="body_track_right_flipper_end" type="fixed">
    <parent link="track_right_flipper"/>
    <child link="track_right_flipper_end"/>
  </joint>

  <link name="track_right_flipper_end">
    <!-- <visual>
      <origin rpy="1.5708 0 0" xyz="0.14 0. 0."/> 
      <geometry>
        <cylinder length="0.05" radius="0.023"/>
      </geometry>
      <material name="Orange"/>
    </visual> -->

    <collision>
      <origin rpy="1.5708 0 0" xyz="0.14 0. 0."/> 
      <geometry>
        <cylinder length="0.05" radius="0.023"/>
      </geometry>
    </collision>

    <inertial>
      <origin rpy="1.5708 0 0" xyz="0.14 0. 0."/> 
      <mass value=".1"/>
      <inertia ixx="0.0000497" ixy="0" ixz="0" iyy="0.0000497" iyz="0" izz="0.0000578"/>
    </inertial>
  </link>


  <joint name="body_track_right_back" type="fixed">
    <parent link="base_link"/>
    <child link="track_right_back"/>
    <origin rpy="0 0 0" xyz="0.254 0.1655 0"/>
    <dynamics damping="0.0"/>
  </joint>

  <link name="track_right_back">
    <!-- <visual>
      <origin rpy="1.5708 0 0" xyz="0 0 0"/> 
      <geometry>
        <cylinder length="0.05" radius="0.033"/>
      </geometry>
      <material name="Orange"/>
    </visual> -->

    <collision>
      <origin rpy="1.5708 0 0" xyz="0 0 0"/> 
      <geometry>
        <cylinder length="0.076" radius="0.082"/>
      </geometry>
    </collision>

    <inertial>
      <origin rpy="1.5708 0 0" xyz="0 0 0"/> 
      <mass value="0.1"/>
      <inertia ixx="0.000497" ixy="0" ixz="0" iyy="0.000497" iyz="0" izz="0.000578"/>
    </inertial>
  </link>

  <!-- Right Wheels -->

    <joint name="body_track_right_wheel_01" type="continuous">
    <parent link="base_link"/>
    <child link="track_right_wheel_01"/>
    <limit effort="30.0" lower="-1.57079632679" upper="1.57079632679" velocity="30.0"/>
    <origin rpy="0 0 0" xyz="-0.254 0.1655 0"/>
    <axis xyz="0 1 0"/>
    <dynamics damping="0.0"/>
  </joint>

  <link name="track_right_wheel_01">
    <!-- <visual>
      <origin rpy="1.5708 0 0" xyz="0 0 0"/> 
      <geometry>
        <cylinder length="0.05" radius="0.06"/>
      </geometry>
      <material name="Orange"/>
    </visual> -->

    <collision>
      <origin rpy="1.5708 0 0" xyz="0 0 0"/> 
      <geometry>
        <cylinder length="0.076" radius="0.082"/>
      </geometry>
    </collision>

    <inertial>
      <origin rpy="1.5708 0 0" xyz="0.0 0.0 0.0"/>
      <mass value="1.49"/>
      <inertia ixx= "0.046" ixy = "0.0" ixz = "0.0" iyy = "0.10" iyz = "0.0" izz = "0.141"/>
      <!-- <inertia ixx="0.000497" ixy="0" ixz="0" iyy="0.000497" iyz="0" izz="0.000578"/> -->
    </inertial>
  </link>

  <joint name="body_track_right_wheel_02" type="continuous">
    <parent link="base_link"/>
    <child link="track_right_wheel_02"/>
    <limit effort="30.0" lower="-1.57079632679" upper="1.57079632679" velocity="30.0"/>
    <origin rpy="0 0 0" xyz="-0.204 0.1655 0"/>
    <axis xyz="0 1 0"/>
    <dynamics damping="0.0"/>
  </joint>

  <link name="track_right_wheel_02">
    <!-- <visual>
      <origin rpy="1.5708 0 0" xyz="0 0 0"/> 
      <geometry>
        <cylinder length="0.05" radius="0.06"/>
      </geometry>
      <material name="Orange"/>
    </visual> -->

    <collision>
      <origin rpy="1.5708 0 0" xyz="0 0 0"/> 
      <geometry>
        <cylinder length="0.076" radius="0.082"/>
      </geometry>
    </collision>

    <inertial>
      <origin rpy="1.5708 0 0" xyz="0.0 0.0 0.0"/>
      <mass value="1.49"/>
      <inertia ixx= "0.046" ixy = "0.0" ixz = "0.0" iyy = "0.10" iyz = "0.0" izz = "0.141"/>
      <!-- <inertia ixx="0.000497" ixy="0" ixz="0" iyy="0.000497" iyz="0" izz="0.000578"/> -->
    </inertial>
  </link>

  <joint name="body_track_right_wheel_03" type="continuous">
    <parent link="base_link"/>
    <child link="track_right_wheel_03"/>
    <limit effort="30.0" lower="-1.57079632679" upper="1.57079632679" velocity="30.0"/>
    <origin rpy="0 0 0" xyz="-0.154 0.1655 0"/>
    <axis xyz="0 1 0"/>
    <dynamics damping="0.0"/>
  </joint>

  <link name="track_right_wheel_03">
    <!-- <visual>
      <origin rpy="1.5708 0 0" xyz="0 0 0"/> 
      <geometry>
        <cylinder length="0.05" radius="0.06"/>
      </geometry>
      <material name="Orange"/>
    </visual> -->

    <collision>
      <origin rpy="1.5708 0 0" xyz="0 0 0"/> 
      <geometry>
        <cylinder length="0.076" radius="0.082"/>
      </geometry>
    </collision>

    <inertial>
      <origin rpy="1.5708 0 0" xyz="0.0 0.0 0.0"/>
      <mass value="1.49"/>
      <inertia ixx= "0.046" ixy = "0.0" ixz = "0.0" iyy = "0.10" iyz = "0.0" izz = "0.141"/>
      <!-- <inertia ixx="0.000497" ixy="0" ixz="0" iyy="0.000497" iyz="0" izz="0.000578"/> -->
    </inertial>
  </link>

  <joint name="body_track_right_wheel_04" type="continuous">
    <parent link="base_link"/>
    <child link="track_right_wheel_04"/>
    <limit effort="30.0" lower="-1.57079632679" upper="1.57079632679" velocity="30.0"/>
    <origin rpy="0 0 0" xyz="-0.104 0.1655 0"/>
    <axis xyz="0 1 0"/>
    <dynamics damping="0.0"/>
  </joint>

  <link name="track_right_wheel_04">
    <!-- <visual>
      <origin rpy="1.5708 0 0" xyz="0 0 0"/> 
      <geometry>
        <cylinder length="0.05" radius="0.06"/>
      </geometry>
      <material name="Orange"/>
    </visual> -->

    <collision>
      <origin rpy="1.5708 0 0" xyz="0 0 0"/> 
      <geometry>
        <cylinder length="0.076" radius="0.082"/>
      </geometry>
    </collision>

    <inertial>
      <origin rpy="1.5708 0 0" xyz="0.0 0.0 0.0"/>
      <mass value="1.49"/>
      <inertia ixx= "0.046" ixy = "0.0" ixz = "0.0" iyy = "0.10" iyz = "0.0" izz = "0.141"/>
      <!-- <inertia ixx="0.000497" ixy="0" ixz="0" iyy="0.000497" iyz="0" izz="0.000578"/> -->
    </inertial>
  </link>

  <joint name="body_track_right_wheel_05" type="continuous">
    <parent link="base_link"/>
    <child link="track_right_wheel_05"/>
    <limit effort="30.0" lower="-1.57079632679" upper="1.57079632679" velocity="30.0"/>
    <origin rpy="0 0 0" xyz="-0.054 0.1655 0"/>
    <axis xyz="0 1 0"/>
    <dynamics damping="0.0"/>
  </joint>

  <link name="track_right_wheel_05">
    <!-- <visual>
      <origin rpy="1.5708 0 0" xyz="0 0 0"/> 
      <geometry>
        <cylinder length="0.05" radius="0.06"/>
      </geometry>
      <material name="Orange"/>
    </visual> -->

    <collision>
      <origin rpy="1.5708 0 0" xyz="0 0 0"/> 
      <geometry>
        <cylinder length="0.076" radius="0.082"/>
      </geometry>
    </collision>

    <inertial>
      <origin rpy="1.5708 0 0" xyz="0.0 0.0 0.0"/>
      <mass value="1.49"/>
      <inertia ixx= "0.046" ixy = "0.0" ixz = "0.0" iyy = "0.10" iyz = "0.0" izz = "0.141"/>
      <!-- <inertia ixx="0.000497" ixy="0" ixz="0" iyy="0.000497" iyz="0" izz="0.000578"/> -->
    </inertial>
  </link>

  <joint name="body_track_right_wheel_06" type="continuous">
    <parent link="base_link"/>
    <child link="track_right_wheel_06"/>
    <limit effort="30.0" lower="-1.57079632679" upper="1.57079632679" velocity="30.0"/>
    <origin rpy="0 0 0" xyz="0.0 0.1655 0"/>
    <axis xyz="0 1 0"/>
    <dynamics damping="0.0"/>
  </joint>

  <link name="track_right_wheel_06">
    <!-- <visual>
      <origin rpy="1.5708 0 0" xyz="0 0 0"/> 
      <geometry>
        <cylinder length="0.05" radius="0.06"/>
      </geometry>
      <material name="Orange"/>
    </visual> -->

    <collision>
      <origin rpy="1.5708 0 0" xyz="0 0 0"/> 
      <geometry>
        <cylinder length="0.076" radius="0.082"/>
      </geometry>
    </collision>

    <inertial>
      <origin rpy="1.5708 0 0" xyz="0.0 0.0 0.0"/>
      <mass value="1.49"/>
      <inertia ixx= "0.046" ixy = "0.0" ixz = "0.0" iyy = "0.10" iyz = "0.0" izz = "0.141"/>
      <!-- <inertia ixx="0.000497" ixy="0" ixz="0" iyy="0.000497" iyz="0" izz="0.000578"/> -->
    </inertial>
  </link>

  <joint name="body_track_right_wheel_07" type="continuous">
    <parent link="base_link"/>
    <child link="track_right_wheel_07"/>
    <limit effort="30.0" lower="-1.57079632679" upper="1.57079632679" velocity="30.0"/>
    <origin rpy="0 0 0" xyz="0.054 0.1655 0"/>
    <axis xyz="0 1 0"/>
    <dynamics damping="0.0"/>
  </joint>

  <link name="track_right_wheel_07">
    <!-- <visual>
      <origin rpy="1.5708 0 0" xyz="0 0 0"/> 
      <geometry>
        <cylinder length="0.05" radius="0.06"/>
      </geometry>
      <material name="Orange"/>
    </visual> -->

    <collision>
      <origin rpy="1.5708 0 0" xyz="0 0 0"/> 
      <geometry>
        <cylinder length="0.076" radius="0.082"/>
      </geometry>
    </collision>

    <inertial>
      <origin rpy="1.5708 0 0" xyz="0.0 0.0 0.0"/>
      <mass value="1.49"/>
      <inertia ixx= "0.046" ixy = "0.0" ixz = "0.0" iyy = "0.10" iyz = "0.0" izz = "0.141"/>
      <!-- <inertia ixx="0.000497" ixy="0" ixz="0" iyy="0.000497" iyz="0" izz="0.000578"/> -->
    </inertial>
  </link>

  <joint name="body_track_right_wheel_08" type="continuous">
    <parent link="base_link"/>
    <child link="track_right_wheel_08"/>
    <limit effort="30.0" lower="-1.57079632679" upper="1.57079632679" velocity="30.0"/>
    <origin rpy="0 0 0" xyz="0.104 0.1655 0"/>
    <axis xyz="0 1 0"/>
    <dynamics damping="0.0"/>
  </joint>

  <link name="track_right_wheel_08">
    <!-- <visual>
      <origin rpy="1.5708 0 0" xyz="0 0 0"/> 
      <geometry>
        <cylinder length="0.05" radius="0.06"/>
      </geometry>
      <material name="Orange"/>
    </visual> -->

    <collision>
      <origin rpy="1.5708 0 0" xyz="0 0 0"/> 
      <geometry>
        <cylinder length="0.076" radius="0.082"/>
      </geometry>
    </collision>

    <inertial>
      <origin rpy="1.5708 0 0" xyz="0.0 0.0 0.0"/>
      <mass value="1.49"/>
      <inertia ixx= "0.046" ixy = "0.0" ixz = "0.0" iyy = "0.10" iyz = "0.0" izz = "0.141"/>
      <!-- <inertia ixx="0.000497" ixy="0" ixz="0" iyy="0.000497" iyz="0" izz="0.000578"/> -->
    </inertial>
  </link>
  <joint name="body_track_right_wheel_09" type="continuous">
    <parent link="base_link"/>
    <child link="track_right_wheel_09"/>
    <limit effort="30.0" lower="-1.57079632679" upper="1.57079632679" velocity="30.0"/>
    <origin rpy="0 0 0" xyz="0.154 0.1655 0"/>
    <axis xyz="0 1 0"/>
    <dynamics damping="0.0"/>
  </joint>

  <link name="track_right_wheel_09">
    <!-- <visual>
      <origin rpy="1.5708 0 0" xyz="0 0 0"/> 
      <geometry>
        <cylinder length="0.05" radius="0.06"/>
      </geometry>
      <material name="Orange"/>
    </visual> -->

    <collision>
      <origin rpy="1.5708 0 0" xyz="0 0 0"/> 
      <geometry>
        <cylinder length="0.076" radius="0.082"/>
      </geometry>
    </collision>

    <inertial>
      <origin rpy="1.5708 0 0" xyz="0.0 0.0 0.0"/>
      <mass value="1.49"/>
      <inertia ixx= "0.046" ixy = "0.0" ixz = "0.0" iyy = "0.10" iyz = "0.0" izz = "0.141"/>
      <!-- <inertia ixx="0.000497" ixy="0" ixz="0" iyy="0.000497" iyz="0" izz="0.000578"/> -->
    </inertial>
  </link>
  <joint name="body_track_right_wheel_10" type="continuous">
    <parent link="base_link"/>
    <child link="track_right_wheel_10"/>
    <limit effort="30.0" lower="-1.57079632679" upper="1.57079632679" velocity="30.0"/>
    <origin rpy="0 0 0" xyz="0.204 0.1655 0"/>
    <axis xyz="0 1 0"/>
    <dynamics damping="0.0"/>
  </joint>

  <link name="track_right_wheel_10">
    <!-- <visual>
      <origin rpy="1.5708 0 0" xyz="0 0 0"/> 
      <geometry>
        <cylinder length="0.05" radius="0.06"/>
      </geometry>
      <material name="Orange"/>
    </visual> -->

    <collision>
      <origin rpy="1.5708 0 0" xyz="0 0 0"/> 
      <geometry>
        <cylinder length="0.076" radius="0.082"/>
      </geometry>
    </collision>

    <inertial>
      <origin rpy="1.5708 0 0" xyz="0.0 0.0 0.0"/>
      <mass value="1.49"/>
      <inertia ixx= "0.046" ixy = "0.0" ixz = "0.0" iyy = "0.10" iyz = "0.0" izz = "0.141"/>
      <!-- <inertia ixx="0.000497" ixy="0" ixz="0" iyy="0.000497" iyz="0" izz="0.000578"/> -->
    </inertial>
  </link>
  <joint name="body_track_right_wheel_11" type="continuous">
    <parent link="base_link"/>
    <child link="track_right_wheel_11"/>
    <limit effort="30.0" lower="-1.57079632679" upper="1.57079632679" velocity="30.0"/>
    <origin rpy="0 0 0" xyz="0.254 0.1655 0"/>
    <axis xyz="0 1 0"/>
    <dynamics damping="0.0"/>
  </joint>

  <link name="track_right_wheel_11">
    <!-- <visual>
      <origin rpy="1.5708 0 0" xyz="0 0 0"/> 
      <geometry>
        <cylinder length="0.05" radius="0.06"/>
      </geometry>
      <material name="Orange"/>
    </visual> -->

    <collision>
      <origin rpy="1.5708 0 0" xyz="0 0 0"/> 
      <geometry>
        <cylinder length="0.076" radius="0.082"/>
      </geometry>
    </collision>

    <inertial>
      <origin rpy="1.5708 0 0" xyz="0.0 0.0 0.0"/>
      <mass value="1.49"/>
      <inertia ixx= "0.046" ixy = "0.0" ixz = "0.0" iyy = "0.10" iyz = "0.0" izz = "0.141"/>
      <!-- <inertia ixx="0.000497" ixy="0" ixz="0" iyy="0.000497" iyz="0" izz="0.000578"/> -->
    </inertial>
  </link>

 
</robot>

