<?xml version="1.0" ?>
<!-- =================================================================================== -->
<!-- |    This document was autogenerated by xacro from urdf/tracked.xacro               | -->
<!-- |    EDITING THIS FILE BY HAND IS NOT RECOMMENDED                                 | -->
<!-- =================================================================================== -->
<robot name="tracked_flipper" xmlns:xacro="http://www.ros.org/wiki/xacro">
  <!-- <xacro:include filename="$(find pexod_description)/urdf/pexod_control.xacro" /> -->
  <!-- MATERIALS -->
  <material name="Blue">
    <color rgba="0 0 1 1"/>
  </material>
  <material name="Red">
    <color rgba="1 0 0 1"/>
  </material>
  <material name="Green">
    <color rgba="0 1 0 1"/>
  </material>
  <material name="Yellow">
    <color rgba="1 1 0 1"/>
  </material>
  <material name="Orange">
    <color rgba="1 0.5 0 1"/>
  </material>
  <material name="LightGrey">
    <color rgba="0.6 0.6 0.6 1.0"/>
  </material>
  <!-- END OF MATERIALS -->
  <!-- XACRO MACROS FOR VISUALS AND COLLISIONS -->
  <!-- END OF XACRO MACROS -->


  <!-- TORSO -->
  <link name="base_link">
    <visual>
      <origin rpy="0 0 0" xyz="0 0 0"/>
      <geometry>
        <box size="0.3 0.2 0.1"/>
      </geometry>
      <material name="Blue"/>
    </visual>
    <collision>
      <origin rpy="0 0 0" xyz="0 0 0"/>
      <geometry>
        <box size="0.3 0.2 0.1"/>
      </geometry>
    </collision>
    <inertial>
      <!-- CENTER OF MASS -->
      <origin rpy="0 0 0" xyz="0 0 0"/>
      <mass value="5"/>
      <!-- <mass value="1.031"/> -->
      <!-- box inertia: 1/12*m(y^2+z^2), ... -->
      <inertia ixx="0.0173333" ixy="0" ixz="0" iyy="0.02466667" iyz="0" izz="0.04066667"/>
    </inertial>
  </link>


  <!-- LINKS/JOINTS -->

  <!-- LEFT TRACK -->

  <joint name="body_track_left" type="fixed">
    <parent link="base_link"/>
    <child link="track_left"/>
    <origin rpy="0 0 0" xyz="0. -0.125 -0.05"/>
    <dynamics damping="0.0"/>
  </joint>

  <link name="track_left">
    <visual>
      <origin rpy="0 0 0" xyz="0 0 0"/> 
      <geometry>
        <box size="0.31 0.05 0.07"/>
      </geometry>
      <material name="Orange"/>
    </visual>

    <collision>
      <origin rpy="0 0 0" xyz="0 0 0"/> 
      <geometry>
        <box size="0.31 0.05 0.07"/>
      </geometry>
    </collision>

    <inertial>
      <!-- CENTER OF MASS -->
      <origin rpy="0 0 0" xyz="0 0 0"/>
      <mass value="1."/>
      <!-- box inertia: 1/12*m(y^2+z^2), ... -->
      <inertia ixx="0.00061667" ixy="0" ixz="0" iyy="0.0420833" iyz="0" izz="0.00821667"/>
    </inertial>
  </link>


  <joint name="body_track_left_front" type="fixed">
    <parent link="track_left"/>
    <child link="track_left_front"/>
    <origin rpy="0 0 0" xyz="-0.155 0 0"/>
    <dynamics damping="0.0"/>
  </joint>

  <link name="track_left_front">
    <visual>
      <origin rpy="1.5708 0 0" xyz="0 0 0"/> 
      <geometry>
        <cylinder length="0.05" radius="0.033"/>
      </geometry>
      <material name="Orange"/>
    </visual>

    <collision>
      <origin rpy="1.5708 0 0" xyz="0 0 0"/> 
      <geometry>
        <cylinder length="0.05" radius="0.033"/>
      </geometry>
    </collision>

    <inertial>
      <origin rpy="1.5708 0 0" xyz="0.0 0.0 0.0"/>
      <mass value="1."/>
      <inertia ixx="0.000497" ixy="0" ixz="0" iyy="0.000497" iyz="0" izz="0.000578"/>
    </inertial>
  </link>

  <!-- WHEELS -->

  <joint name="body_track_left_wheel_1" type="continuous">
    <parent link="track_left"/>
    <child link="track_left_wheel_1"/>
    <limit effort="30.0" lower="-1.57079632679" upper="1.57079632679" velocity="30.0"/>
    <origin rpy="0 0 0" xyz="-0.155 0 0"/>
    <axis xyz="0 1 0"/>
    <dynamics damping="0.0"/>
  </joint>

  <link name="track_left_wheel_1">
    <visual>
      <origin rpy="1.5708 0 0" xyz="0 0 0"/> 
      <geometry>
        <cylinder length="0.05" radius="0.06"/>
      </geometry>
      <material name="Orange"/>
    </visual>

    <collision>
      <origin rpy="1.5708 0 0" xyz="0 0 0"/> 
      <geometry>
        <cylinder length="0.05" radius="0.06"/>
      </geometry>
    </collision>

    <inertial>
      <origin rpy="1.5708 0 0" xyz="0.0 0.0 0.0"/>
      <mass value="0.1"/>
      <inertia ixx="0.000497" ixy="0" ixz="0" iyy="0.000497" iyz="0" izz="0.000578"/>
    </inertial>
  </link>

  <joint name="body_track_left_wheel_2" type="continuous">
    <parent link="track_left"/>
    <child link="track_left_wheel_2"/>
    <limit effort="30.0" lower="-1.57079632679" upper="1.57079632679" velocity="30.0"/>
    <origin rpy="0 0 0" xyz="-0.105 0 0"/>
    <axis xyz="0 1 0"/>
    <dynamics damping="0.0"/>
  </joint>

  <link name="track_left_wheel_2">
    <visual>
      <origin rpy="1.5708 0 0" xyz="0 0 0"/> 
      <geometry>
        <cylinder length="0.05" radius="0.06"/>
      </geometry>
      <material name="Orange"/>
    </visual>

    <collision>
      <origin rpy="1.5708 0 0" xyz="0 0 0"/> 
      <geometry>
        <cylinder length="0.05" radius="0.06"/>
      </geometry>
    </collision>

    <inertial>
      <origin rpy="1.5708 0 0" xyz="0.0 0.0 0.0"/>
      <mass value="0.1"/>
      <inertia ixx="0.000497" ixy="0" ixz="0" iyy="0.000497" iyz="0" izz="0.000578"/>
    </inertial>
  </link>

  <joint name="body_track_left_wheel_3" type="continuous">
    <parent link="track_left"/>
    <child link="track_left_wheel_3"/>
    <limit effort="30.0" lower="-1.57079632679" upper="1.57079632679" velocity="30.0"/>
    <origin rpy="0 0 0" xyz="-0.055 0 0"/>
    <axis xyz="0 1 0"/>
    <dynamics damping="0.0"/>
  </joint>

  <link name="track_left_wheel_3">
    <visual>
      <origin rpy="1.5708 0 0" xyz="0 0 0"/> 
      <geometry>
        <cylinder length="0.05" radius="0.06"/>
      </geometry>
      <material name="Orange"/>
    </visual>

    <collision>
      <origin rpy="1.5708 0 0" xyz="0 0 0"/> 
      <geometry>
        <cylinder length="0.05" radius="0.06"/>
      </geometry>
    </collision>

    <inertial>
      <origin rpy="1.5708 0 0" xyz="0.0 0.0 0.0"/>
      <mass value="0.1"/>
      <inertia ixx="0.000497" ixy="0" ixz="0" iyy="0.000497" iyz="0" izz="0.000578"/>
    </inertial>
  </link>

  <joint name="body_track_left_wheel_4" type="continuous">
    <parent link="track_left"/>
    <child link="track_left_wheel_4"/>
    <limit effort="30.0" lower="-1.57079632679" upper="1.57079632679" velocity="30.0"/>
    <origin rpy="0 0 0" xyz="-0.0 0 0"/>
    <axis xyz="0 1 0"/>
    <dynamics damping="0.0"/>
  </joint>

  <link name="track_left_wheel_4">
    <visual>
      <origin rpy="1.5708 0 0" xyz="0 0 0"/> 
      <geometry>
        <cylinder length="0.05" radius="0.06"/>
      </geometry>
      <material name="Orange"/>
    </visual>

    <collision>
      <origin rpy="1.5708 0 0" xyz="0 0 0"/> 
      <geometry>
        <cylinder length="0.05" radius="0.06"/>
      </geometry>
    </collision>

    <inertial>
      <origin rpy="1.5708 0 0" xyz="0.0 0.0 0.0"/>
      <mass value="0.1"/>
      <inertia ixx="0.000497" ixy="0" ixz="0" iyy="0.000497" iyz="0" izz="0.000578"/>
    </inertial>
  </link>

  <joint name="body_track_left_wheel_5" type="continuous">
    <parent link="track_left"/>
    <child link="track_left_wheel_5"/>
    <limit effort="30.0" lower="-1.57079632679" upper="1.57079632679" velocity="30.0"/>
    <origin rpy="0 0 0" xyz="0.055 0 0"/>
    <axis xyz="0 1 0"/>
    <dynamics damping="0.0"/>
  </joint>

  <link name="track_left_wheel_5">
    <visual>
      <origin rpy="1.5708 0 0" xyz="0 0 0"/> 
      <geometry>
        <cylinder length="0.05" radius="0.06"/>
      </geometry>
      <material name="Orange"/>
    </visual>

    <collision>
      <origin rpy="1.5708 0 0" xyz="0 0 0"/> 
      <geometry>
        <cylinder length="0.05" radius="0.06"/>
      </geometry>
    </collision>

    <inertial>
      <origin rpy="1.5708 0 0" xyz="0.0 0.0 0.0"/>
      <mass value="0.1"/>
      <inertia ixx="0.000497" ixy="0" ixz="0" iyy="0.000497" iyz="0" izz="0.000578"/>
    </inertial>
  </link>

  <joint name="body_track_left_wheel_6" type="continuous">
    <parent link="track_left"/>
    <child link="track_left_wheel_6"/>
    <limit effort="30.0" lower="-1.57079632679" upper="1.57079632679" velocity="30.0"/>
    <origin rpy="0 0 0" xyz="0.105 0 0"/>
    <axis xyz="0 1 0"/>
    <dynamics damping="0.0"/>
  </joint>

  <link name="track_left_wheel_6">
    <visual>
      <origin rpy="1.5708 0 0" xyz="0 0 0"/> 
      <geometry>
        <cylinder length="0.05" radius="0.06"/>
      </geometry>
      <material name="Orange"/>
    </visual>

    <collision>
      <origin rpy="1.5708 0 0" xyz="0 0 0"/> 
      <geometry>
        <cylinder length="0.05" radius="0.06"/>
      </geometry>
    </collision>

    <inertial>
      <origin rpy="1.5708 0 0" xyz="0.0 0.0 0.0"/>
      <mass value="0.1"/>
      <inertia ixx="0.000497" ixy="0" ixz="0" iyy="0.000497" iyz="0" izz="0.000578"/>
    </inertial>
  </link>

  <joint name="body_track_left_wheel_7" type="continuous">
    <parent link="track_left"/>
    <child link="track_left_wheel_7"/>
    <limit effort="30.0" lower="-1.57079632679" upper="1.57079632679" velocity="30.0"/>
    <origin rpy="0 0 0" xyz="0.155 0 0"/>
    <axis xyz="0 1 0"/>
    <dynamics damping="0.0"/>
  </joint>

  <link name="track_left_wheel_7">
    <visual>
      <origin rpy="1.5708 0 0" xyz="0 0 0"/> 
      <geometry>
        <cylinder length="0.05" radius="0.06"/>
      </geometry>
      <material name="Orange"/>
    </visual>

    <collision>
      <origin rpy="1.5708 0 0" xyz="0 0 0"/> 
      <geometry>
        <cylinder length="0.05" radius="0.06"/>
      </geometry>
    </collision>

    <inertial>
      <origin rpy="1.5708 0 0" xyz="0.0 0.0 0.0"/>
      <mass value="0.1"/>
      <inertia ixx="0.000497" ixy="0" ixz="0" iyy="0.000497" iyz="0" izz="0.000578"/>
    </inertial>
  </link>

  <joint name="body_track_left_flipper" type="revolute">
    <parent link="track_left_front"/>
    <child link="track_left_flipper"/>
    <limit effort="30.0" lower="-1.57079632679" upper="1.57079632679" velocity="7.0"/>
    <origin rpy="0 3.14 0" xyz="0 -0.05 0"/>
    <axis xyz="0 1 0"/>
    <dynamics damping="0.0"/>
  </joint>

  <link name="track_left_flipper">
    <visual>
      <origin rpy="0 0 0" xyz="0.07 0. 0."/> 
      <geometry>
        <box size="0.15 0.05 0.05"/>
      </geometry>
      <material name="Red"/>
    </visual>

    <collision>
      <origin rpy="0 0 0" xyz="0.07 0. 0."/> 
      <geometry>
        <box size="0.15 0.05 0.05"/>
      </geometry>
    </collision>

    <inertial>
      <!-- CENTER OF MASS -->
      <origin rpy="0 0 0" xyz="0.07 0. 0."/> 
      <mass value=".5"/>
      <!-- box inertia: 1/12*m(y^2+z^2), ... -->
      <inertia ixx="0.00020833" ixy="0" ixz="0" iyy="0.001770833" iyz="0" izz="0.001770833"/>
    </inertial>
  </link>


  <joint name="body_track_left_flipper_end" type="fixed">
    <parent link="track_left_flipper"/>
    <child link="track_left_flipper_end"/>
  </joint>

  <link name="track_left_flipper_end">
    <visual>
      <origin rpy="1.5708 0 0" xyz="0.14 0. 0."/> 
      <geometry>
        <cylinder length="0.05" radius="0.023"/>
      </geometry>
      <material name="Orange"/>
    </visual>

    <collision>
      <origin rpy="1.5708 0 0" xyz="0.14 0. 0."/> 
      <geometry>
        <cylinder length="0.05" radius="0.023"/>
      </geometry>
    </collision>

    <inertial>
      <origin rpy="1.5708 0 0" xyz="0.14 0. 0."/> 
      <mass value=".1"/>
      <inertia ixx="0.0000497" ixy="0" ixz="0" iyy="0.0000497" iyz="0" izz="0.0000578"/>
    </inertial>
  </link>

  <joint name="body_track_left_back" type="fixed">
    <parent link="track_left"/>
    <child link="track_left_back"/>
    <origin rpy="0 0 0" xyz="0.155 0 0"/>
    <axis xyz="0 1 0"/>
    <dynamics damping="0.0"/>
  </joint>

  <link name="track_left_back">
    <visual>
      <origin rpy="1.5708 0 0" xyz="0 0 0"/> 
      <geometry>
        <cylinder length="0.05" radius="0.033"/>
      </geometry>
      <material name="Orange"/>
    </visual>

    <collision>
      <origin rpy="1.5708 0 0" xyz="0 0 0"/> 
      <geometry>
        <cylinder length="0.05" radius="0.033"/>
      </geometry>
    </collision>

    <inertial>
      <origin rpy="1.5708 0 0" xyz="0 0 0"/> 
      <mass value="1."/>
      <inertia ixx="0.000497" ixy="0" ixz="0" iyy="0.000497" iyz="0" izz="0.000578"/>
    </inertial>
  </link>

  <!-- RIGHT TRACK -->

  <joint name="body_track_right" type="fixed">
    <parent link="base_link"/>
    <child link="track_right"/>
     <origin rpy="0 0 0" xyz="0. 0.125 -0.05"/>
    <dynamics damping="0.0"/>
  </joint>

  <link name="track_right">
    <visual>
      <origin rpy="0 0 0" xyz="0. 0 0"/> 
      <geometry>
        <box size="0.31 0.05 0.07"/>
      </geometry>
      <material name="Orange"/>
    </visual>

    <collision>
      <origin rpy="0 0 0" xyz="0. 0 0"/> 
      <geometry>
        <box size="0.31 0.05 0.07"/>
      </geometry>
    </collision>

    <inertial>
      <!-- CENTER OF MASS -->
      <origin rpy="0 0 0" xyz="0. 0 0"/> 
      <mass value="1."/>
      <!-- box inertia: 1/12*m(y^2+z^2), ... -->
      <inertia ixx="0.00061667" ixy="0" ixz="0" iyy="0.0420833" iyz="0" izz="0.00821667"/>
    </inertial>
  </link>

  
  <joint name="body_track_right_front" type="fixed">
    <parent link="track_right"/>
    <child link="track_right_front"/>
    <origin rpy="0 0 0" xyz="-0.155 0 0"/>
    <dynamics damping="0.0"/>
  </joint>

  <link name="track_right_front">
    <visual>
      <origin rpy="1.5708 0 0" xyz="0 0 0"/> 
      <geometry>
        <cylinder length="0.05" radius="0.033"/>
      </geometry>
      <material name="Orange"/>
    </visual>

    <collision>
      <origin rpy="1.5708 0 0" xyz="0 0 0"/> 
      <geometry>
        <cylinder length="0.05" radius="0.033"/>
      </geometry>
    </collision>

    <inertial>
      <origin rpy="1.5708 0 0" xyz="0 0 0"/> 
      <mass value="1."/>
      <inertia ixx="0.000497" ixy="0" ixz="0" iyy="0.000497" iyz="0" izz="0.000578"/>
    </inertial>
  </link>

  <joint name="body_track_right_flipper" type="revolute">
    <parent link="track_right_front"/>
    <child link="track_right_flipper"/>
    <limit effort="30.0" lower="-1.57079632679" upper="1.57079632679" velocity="7.0"/>
    <origin rpy="0 3.14 0" xyz="0 0.05 0"/>
    <axis xyz="0 1 0"/>
    <dynamics damping="0.0"/>
  </joint>

  <link name="track_right_flipper">
    <visual>
      <origin rpy="0 0 0" xyz="0.07 0. 0."/> 
      <geometry>
        <box size="0.15 0.05 0.05"/>
      </geometry>
      <material name="Red"/>
    </visual>

    <collision>
      <origin rpy="0 0 0" xyz="0.07 0. 0."/> 
      <geometry>
        <box size="0.15 0.05 0.05"/>
      </geometry>
    </collision>

    <inertial>
      <!-- CENTER OF MASS -->
      <origin rpy="0 0 0" xyz="0.07 0. 0."/> 
      <mass value=".5"/>
      <!-- box inertia: 1/12*m(y^2+z^2), ... -->
      <inertia ixx="0.00020833" ixy="0" ixz="0" iyy="0.001770833" iyz="0" izz="0.001770833"/>
    </inertial>
  </link>

  <joint name="body_track_right_flipper_end" type="fixed">
    <parent link="track_right_flipper"/>
    <child link="track_right_flipper_end"/>
  </joint>

  <link name="track_right_flipper_end">
    <visual>
      <origin rpy="1.5708 0 0" xyz="0.14 0. 0."/> 
      <geometry>
        <cylinder length="0.05" radius="0.023"/>
      </geometry>
      <material name="Orange"/>
    </visual>

    <collision>
      <origin rpy="1.5708 0 0" xyz="0.14 0. 0."/> 
      <geometry>
        <cylinder length="0.05" radius="0.023"/>
      </geometry>
    </collision>

    <inertial>
      <origin rpy="1.5708 0 0" xyz="0.14 0. 0."/> 
      <mass value=".1"/>
      <inertia ixx="0.0000497" ixy="0" ixz="0" iyy="0.0000497" iyz="0" izz="0.0000578"/>
    </inertial>
  </link>


  <joint name="body_track_right_back" type="fixed">
    <parent link="track_right"/>
    <child link="track_right_back"/>
    <origin rpy="0 0 0" xyz="0.155 0 0"/>
    <dynamics damping="0.0"/>
  </joint>

  <link name="track_right_back">
    <visual>
      <origin rpy="1.5708 0 0" xyz="0 0 0"/> 
      <geometry>
        <cylinder length="0.05" radius="0.033"/>
      </geometry>
      <material name="Orange"/>
    </visual>

    <collision>
      <origin rpy="1.5708 0 0" xyz="0 0 0"/> 
      <geometry>
        <cylinder length="0.05" radius="0.033"/>
      </geometry>
    </collision>

    <inertial>
      <origin rpy="1.5708 0 0" xyz="0 0 0"/> 
      <mass value="1."/>
      <inertia ixx="0.000497" ixy="0" ixz="0" iyy="0.000497" iyz="0" izz="0.000578"/>
    </inertial>
  </link>

  <!-- Right Wheels -->

    <joint name="body_track_right_wheel_1" type="continuous">
    <parent link="track_right"/>
    <child link="track_right_wheel_1"/>
    <limit effort="30.0" lower="-1.57079632679" upper="1.57079632679" velocity="30.0"/>
    <origin rpy="0 0 0" xyz="-0.155 0 0"/>
    <axis xyz="0 1 0"/>
    <dynamics damping="0.0"/>
  </joint>

  <link name="track_right_wheel_1">
    <visual>
      <origin rpy="1.5708 0 0" xyz="0 0 0"/> 
      <geometry>
        <cylinder length="0.05" radius="0.06"/>
      </geometry>
      <material name="Orange"/>
    </visual>

    <collision>
      <origin rpy="1.5708 0 0" xyz="0 0 0"/> 
      <geometry>
        <cylinder length="0.05" radius="0.06"/>
      </geometry>
    </collision>

    <inertial>
      <origin rpy="1.5708 0 0" xyz="0.0 0.0 0.0"/>
      <mass value="0.1"/>
      <inertia ixx="0.000497" ixy="0" ixz="0" iyy="0.000497" iyz="0" izz="0.000578"/>
    </inertial>
  </link>

  <joint name="body_track_right_wheel_2" type="continuous">
    <parent link="track_right"/>
    <child link="track_right_wheel_2"/>
    <limit effort="30.0" lower="-1.57079632679" upper="1.57079632679" velocity="30.0"/>
    <origin rpy="0 0 0" xyz="-0.105 0 0"/>
    <axis xyz="0 1 0"/>
    <dynamics damping="0.0"/>
  </joint>

  <link name="track_right_wheel_2">
    <visual>
      <origin rpy="1.5708 0 0" xyz="0 0 0"/> 
      <geometry>
        <cylinder length="0.05" radius="0.06"/>
      </geometry>
      <material name="Orange"/>
    </visual>

    <collision>
      <origin rpy="1.5708 0 0" xyz="0 0 0"/> 
      <geometry>
        <cylinder length="0.05" radius="0.06"/>
      </geometry>
    </collision>

    <inertial>
      <origin rpy="1.5708 0 0" xyz="0.0 0.0 0.0"/>
      <mass value="0.1"/>
      <inertia ixx="0.000497" ixy="0" ixz="0" iyy="0.000497" iyz="0" izz="0.000578"/>
    </inertial>
  </link>

  <joint name="body_track_right_wheel_3" type="continuous">
    <parent link="track_right"/>
    <child link="track_right_wheel_3"/>
    <limit effort="30.0" lower="-1.57079632679" upper="1.57079632679" velocity="30.0"/>
    <origin rpy="0 0 0" xyz="-0.055 0 0"/>
    <axis xyz="0 1 0"/>
    <dynamics damping="0.0"/>
  </joint>

  <link name="track_right_wheel_3">
    <visual>
      <origin rpy="1.5708 0 0" xyz="0 0 0"/> 
      <geometry>
        <cylinder length="0.05" radius="0.06"/>
      </geometry>
      <material name="Orange"/>
    </visual>

    <collision>
      <origin rpy="1.5708 0 0" xyz="0 0 0"/> 
      <geometry>
        <cylinder length="0.05" radius="0.06"/>
      </geometry>
    </collision>

    <inertial>
      <origin rpy="1.5708 0 0" xyz="0.0 0.0 0.0"/>
      <mass value="0.1"/>
      <inertia ixx="0.000497" ixy="0" ixz="0" iyy="0.000497" iyz="0" izz="0.000578"/>
    </inertial>
  </link>

  <joint name="body_track_right_wheel_4" type="continuous">
    <parent link="track_right"/>
    <child link="track_right_wheel_4"/>
    <limit effort="30.0" lower="-1.57079632679" upper="1.57079632679" velocity="30.0"/>
    <origin rpy="0 0 0" xyz="-0.0 0 0"/>
    <axis xyz="0 1 0"/>
    <dynamics damping="0.0"/>
  </joint>

  <link name="track_right_wheel_4">
    <visual>
      <origin rpy="1.5708 0 0" xyz="0 0 0"/> 
      <geometry>
        <cylinder length="0.05" radius="0.06"/>
      </geometry>
      <material name="Orange"/>
    </visual>

    <collision>
      <origin rpy="1.5708 0 0" xyz="0 0 0"/> 
      <geometry>
        <cylinder length="0.05" radius="0.06"/>
      </geometry>
    </collision>

    <inertial>
      <origin rpy="1.5708 0 0" xyz="0.0 0.0 0.0"/>
      <mass value="0.1"/>
      <inertia ixx="0.000497" ixy="0" ixz="0" iyy="0.000497" iyz="0" izz="0.000578"/>
    </inertial>
  </link>

  <joint name="body_track_right_wheel_5" type="continuous">
    <parent link="track_right"/>
    <child link="track_right_wheel_5"/>
    <limit effort="30.0" lower="-1.57079632679" upper="1.57079632679" velocity="30.0"/>
    <origin rpy="0 0 0" xyz="0.055 0 0"/>
    <axis xyz="0 1 0"/>
    <dynamics damping="0.0"/>
  </joint>

  <link name="track_right_wheel_5">
    <visual>
      <origin rpy="1.5708 0 0" xyz="0 0 0"/> 
      <geometry>
        <cylinder length="0.05" radius="0.06"/>
      </geometry>
      <material name="Orange"/>
    </visual>

    <collision>
      <origin rpy="1.5708 0 0" xyz="0 0 0"/> 
      <geometry>
        <cylinder length="0.05" radius="0.06"/>
      </geometry>
    </collision>

    <inertial>
      <origin rpy="1.5708 0 0" xyz="0.0 0.0 0.0"/>
      <mass value="0.1"/>
      <inertia ixx="0.000497" ixy="0" ixz="0" iyy="0.000497" iyz="0" izz="0.000578"/>
    </inertial>
  </link>

  <joint name="body_track_right_wheel_6" type="continuous">
    <parent link="track_right"/>
    <child link="track_right_wheel_6"/>
    <limit effort="30.0" lower="-1.57079632679" upper="1.57079632679" velocity="30.0"/>
    <origin rpy="0 0 0" xyz="0.105 0 0"/>
    <axis xyz="0 1 0"/>
    <dynamics damping="0.0"/>
  </joint>

  <link name="track_right_wheel_6">
    <visual>
      <origin rpy="1.5708 0 0" xyz="0 0 0"/> 
      <geometry>
        <cylinder length="0.05" radius="0.06"/>
      </geometry>
      <material name="Orange"/>
    </visual>

    <collision>
      <origin rpy="1.5708 0 0" xyz="0 0 0"/> 
      <geometry>
        <cylinder length="0.05" radius="0.06"/>
      </geometry>
    </collision>

    <inertial>
      <origin rpy="1.5708 0 0" xyz="0.0 0.0 0.0"/>
      <mass value="0.1"/>
      <inertia ixx="0.000497" ixy="0" ixz="0" iyy="0.000497" iyz="0" izz="0.000578"/>
    </inertial>
  </link>

  <joint name="body_track_right_wheel_7" type="continuous">
    <parent link="track_right"/>
    <child link="track_right_wheel_7"/>
    <limit effort="30.0" lower="-1.57079632679" upper="1.57079632679" velocity="30.0"/>
    <origin rpy="0 0 0" xyz="0.155 0 0"/>
    <axis xyz="0 1 0"/>
    <dynamics damping="0.0"/>
  </joint>

  <link name="track_right_wheel_7">
    <visual>
      <origin rpy="1.5708 0 0" xyz="0 0 0"/> 
      <geometry>
        <cylinder length="0.05" radius="0.06"/>
      </geometry>
      <material name="Orange"/>
    </visual>

    <collision>
      <origin rpy="1.5708 0 0" xyz="0 0 0"/> 
      <geometry>
        <cylinder length="0.05" radius="0.06"/>
      </geometry>
    </collision>

    <inertial>
      <origin rpy="1.5708 0 0" xyz="0.0 0.0 0.0"/>
      <mass value="0.1"/>
      <inertia ixx="0.000497" ixy="0" ixz="0" iyy="0.000497" iyz="0" izz="0.000578"/>
    </inertial>
  </link>

 
</robot>

