<?xml version="1.0" ?>
<!-- =================================================================================== -->
<!-- |    This document was autogenerated by xacro from urdf/tracked.xacro               | -->
<!-- |    EDITING THIS FILE BY HAND IS NOT RECOMMENDED                                 | -->
<!-- =================================================================================== -->
<robot name="gvrbot_updated" xmlns:xacro="http://www.ros.org/wiki/xacro">
  <!-- <xacro:include filename="$(find pexod_description)/urdf/pexod_control.xacro" /> -->
  <!-- MATERIALS -->
  <material name="Blue">
    <color rgba="0 0 1 1"/>
  </material>
  <material name="Red">
    <color rgba="1 0 0 1"/>
  </material>
  <material name="Green">
    <color rgba="0 1 0 1"/>
  </material>
  <material name="Yellow">
    <color rgba="1 1 0 1"/>
  </material>
  <material name="Orange">
    <color rgba="1 0.5 0 1"/>
  </material>
  <material name="LightGrey">
    <color rgba="0.6 0.6 0.6 1.0"/>
  </material>
  <material name="White">
    <color rgba="1 1 1 1"/>
  </material>

  <!-- END OF MATERIALS -->
  <!-- XACRO MACROS FOR VISUALS AND COLLISIONS -->
  <!-- END OF XACRO MACROS -->

  <!-- TORSO -->
  <link name="base_link">
    <!---->
    <visual>
      <origin rpy="0 0 0" xyz="0 0 0"/>
      <geometry>
        <box size="0.588 0.254 0.06"/>
      </geometry>
      <material name="Black"/>
    </visual>
    
    <!--
    <visual>
      <origin rpy="0 0 3.14159" xyz="0 0 0"/>
      <geometry>
        <mesh filename="gvr_bot/Base_Centered_Stripped.obj" scale="1.0 1.0 1.0" />
      </geometry>
    </visual>
    -->
    <collision>
      <origin rpy="0 0 0" xyz="0 0 0"/>
      <geometry>
        <box size="0.588 0.254 0.06"/>
      </geometry>
    </collision>

    <inertial>
      <!-- CENTER OF MASS -->
      <origin rpy="0 0 0" xyz="0.03608 0.02822 0"/>
      <mass value="16.9"/>
      <inertia ixx="0.2739" ixy="-0.01732" ixz="0.0142" iyy="0.4754" iyz="-0.00360" izz="0.6768"/>
      <!-- <inertia ixx="0.0173333" ixy="0" ixz="0" iyy="0.02466667" iyz="0" izz="0.04066667"/> -->
    </inertial>
  </link>
  <!-- LINKS/JOINTS -->

  <!-- WHEEELS-->

  <!-- Left Track -->

  <joint name="base_to_L1_wheel" type="continuous">
        <parent link="base_link"/>
        <child link="L1"/> 
        <axis xyz="0 1 0"/>
        <!-- Add 1/2 wheel thickness + 7 mm for the y offset-->
        <!-- Add the (685 mm) track length/2 - wheel radius for the maximal x offset-->
        <!-- Subtract the position of the wheel base above ground (39.5 mm) from wheel radius for the z offset-->
        <origin xyz="-0.2605 -0.1721 0.0125"/>
  </joint>

  <link name="L1">
      <visual> 
          <geometry> 
              <cylinder length="0.0762" radius="0.082"/>
          </geometry>
          <origin rpy="1.57075 0 0"/>
          <material name="White"/>
      </visual>
      <collision> 
            <geometry> 
              <cylinder length="0.0762" radius="0.082"/>
          </geometry>
          <origin rpy="1.57075 0 0"/>
      </collision> 
      <inertial> 
          <origin rpy="1.57075 0 0"/>
          <mass value="0.06227"/>
          <inertia ixx="0.0001348" ixy="0" ixz="0" iyy="0.0001348" iyz="0" izz="0.00020935"/>
      </inertial> 
  </link> 

  <joint name="base_to_L2_wheel" type="continuous">
        <parent link="base_link"/>
        <child link="L2"/> 
        <axis xyz="0 1 0"/>
        <origin xyz="-0.2084 -0.1721 0.0125"/>
  </joint>

  <link name="L2">
      <visual> 
          <geometry> 
              <cylinder length="0.0762" radius="0.082"/>
          </geometry>
          <origin rpy="1.57075 0 0"/>
          <material name="White"/>
      </visual>
      <collision> 
            <geometry> 
              <cylinder length="0.0762" radius="0.082"/>
          </geometry>
          <origin rpy="1.57075 0 0"/>
      </collision> 
      <inertial> 
          <origin rpy="1.57075 0 0"/>
          <mass value="0.06227"/>
          <inertia ixx="0.0001348" ixy="0" ixz="0" iyy="0.0001348" iyz="0" izz="0.00020935"/>
      </inertial> 
  </link> 

  <joint name="base_to_L3_wheel" type="continuous">
        <parent link="base_link"/>
        <child link="L3"/> 
        <axis xyz="0 1 0"/>
        <origin xyz="-0.1563 -0.1721 0.0125"/>
  </joint>

  <link name="L3">
      <visual> 
          <geometry> 
              <cylinder length="0.0762" radius="0.082"/>
          </geometry>
          <origin rpy="1.57075 0 0"/>
          <material name="White"/>
      </visual>
      <collision> 
            <geometry> 
              <cylinder length="0.0762" radius="0.082"/>
          </geometry>
          <origin rpy="1.57075 0 0"/>
      </collision> 
      <inertial> 
          <origin rpy="1.57075 0 0"/>
          <mass value="0.06227"/>
          <inertia ixx="0.0001348" ixy="0" ixz="0" iyy="0.0001348" iyz="0" izz="0.00020935"/>
      </inertial> 
  </link> 
  
  <joint name="base_to_L4_wheel" type="continuous">
        <parent link="base_link"/>
        <child link="L4"/> 
        <axis xyz="0 1 0"/>
        <origin xyz="-0.1042 -0.1721 0.0125"/>
  </joint>

  <link name="L4">
      <visual> 
          <geometry> 
              <cylinder length="0.0762" radius="0.082"/>
          </geometry>
          <origin rpy="1.57075 0 0"/>
          <material name="White"/>
      </visual>
      <collision> 
            <geometry> 
              <cylinder length="0.0762" radius="0.082"/>
          </geometry>
          <origin rpy="1.57075 0 0"/>
      </collision> 
      <inertial> 
          <origin rpy="1.57075 0 0"/>
          <mass value="0.06227"/>
          <inertia ixx="0.0001348" ixy="0" ixz="0" iyy="0.0001348" iyz="0" izz="0.00020935"/>
      </inertial> 
  </link> 

  <joint name="base_to_L5_wheel" type="continuous">
        <parent link="base_link"/>
        <child link="L5"/> 
        <axis xyz="0 1 0"/>
        <origin xyz="-0.0521 -0.1721 0.0125"/>
  </joint>

  <link name="L5">
      <visual> 
          <geometry> 
              <cylinder length="0.0762" radius="0.082"/>
          </geometry>
          <origin rpy="1.57075 0 0"/>
          <material name="White"/>
      </visual>
      <collision> 
            <geometry> 
              <cylinder length="0.0762" radius="0.082"/>
          </geometry>
          <origin rpy="1.57075 0 0"/>
      </collision> 
      <inertial> 
          <origin rpy="1.57075 0 0"/>
          <mass value="0.06227"/>
          <inertia ixx="0.0001348" ixy="0" ixz="0" iyy="0.0001348" iyz="0" izz="0.00020935"/>
      </inertial> 
  </link> 

  <joint name="base_to_L6_wheel" type="continuous">
        <parent link="base_link"/>
        <child link="L6"/> 
        <axis xyz="0 1 0"/>
        <origin xyz="0 -0.1721 0.0125"/>
  </joint>

  <link name="L6">
      <visual> 
          <geometry> 
              <cylinder length="0.0762" radius="0.082"/>
          </geometry>
          <origin rpy="1.57075 0 0"/>
          <material name="White"/>
      </visual>
      <collision> 
            <geometry> 
              <cylinder length="0.0762" radius="0.082"/>
          </geometry>
          <origin rpy="1.57075 0 0"/>
      </collision> 
      <inertial> 
          <origin rpy="1.57075 0 0"/>
          <mass value="0.06227"/>
          <inertia ixx="0.0001348" ixy="0" ixz="0" iyy="0.0001348" iyz="0" izz="0.00020935"/>
      </inertial> 
  </link> 

  <joint name="base_to_L7_wheel" type="continuous">
        <parent link="base_link"/>
        <child link="L7"/> 
        <axis xyz="0 1 0"/>
        <origin xyz="0.0521 -0.1721 0.0125"/>
  </joint>

  <link name="L7">
      <visual> 
          <geometry> 
              <cylinder length="0.0762" radius="0.082"/>
          </geometry>
          <origin rpy="1.57075 0 0"/>
          <material name="White"/>
      </visual>
      <collision> 
            <geometry> 
              <cylinder length="0.0762" radius="0.082"/>
          </geometry>
          <origin rpy="1.57075 0 0"/>
      </collision> 
      <inertial> 
          <origin rpy="1.57075 0 0"/>
          <mass value="0.06227"/>
          <inertia ixx="0.0001348" ixy="0" ixz="0" iyy="0.0001348" iyz="0" izz="0.00020935"/>
      </inertial> 
  </link> 

  <joint name="base_to_L8_wheel" type="continuous">
        <parent link="base_link"/>
        <child link="L8"/> 
        <axis xyz="0 1 0"/>
        <origin xyz="0.1042 -0.1721 0.0125"/>
  </joint>

  <link name="L8">
      <visual> 
          <geometry> 
              <cylinder length="0.0762" radius="0.082"/>
          </geometry>
          <origin rpy="1.57075 0 0"/>
          <material name="White"/>
      </visual>
      <collision> 
            <geometry> 
              <cylinder length="0.0762" radius="0.082"/>
          </geometry>
          <origin rpy="1.57075 0 0"/>
      </collision> 
      <inertial> 
          <origin rpy="1.57075 0 0"/>
          <mass value="0.06227"/>
          <inertia ixx="0.0001348" ixy="0" ixz="0" iyy="0.0001348" iyz="0" izz="0.00020935"/>
      </inertial> 
  </link> 

  <joint name="base_to_L9_wheel" type="continuous">
        <parent link="base_link"/>
        <child link="L9"/> 
        <axis xyz="0 1 0"/>
        <origin xyz="0.1563 -0.1721 0.0125"/>
  </joint>

  <link name="L9">
      <visual> 
          <geometry> 
              <cylinder length="0.0762" radius="0.082"/>
          </geometry>
          <origin rpy="1.57075 0 0"/>
          <material name="White"/>
      </visual>
      <collision> 
            <geometry> 
              <cylinder length="0.0762" radius="0.082"/>
          </geometry>
          <origin rpy="1.57075 0 0"/>
      </collision> 
      <inertial> 
          <origin rpy="1.57075 0 0"/>
          <mass value="0.06227"/>
          <inertia ixx="0.0001348" ixy="0" ixz="0" iyy="0.0001348" iyz="0" izz="0.00020935"/>
      </inertial> 
  </link> 

  <joint name="base_to_L10_wheel" type="continuous">
        <parent link="base_link"/>
        <child link="L10"/> 
        <axis xyz="0 1 0"/>
        <origin xyz="0.2084 -0.1721 0.0125"/>
  </joint>

  <link name="L10">
      <visual> 
          <geometry> 
              <cylinder length="0.0762" radius="0.082"/>
          </geometry>
          <origin rpy="1.57075 0 0"/>
          <material name="White"/>
      </visual>
      <collision> 
            <geometry> 
              <cylinder length="0.0762" radius="0.082"/>
          </geometry>
          <origin rpy="1.57075 0 0"/>
      </collision> 
      <inertial> 
          <origin rpy="1.57075 0 0"/>
          <mass value="0.06227"/>
          <inertia ixx="0.0001348" ixy="0" ixz="0" iyy="0.0001348" iyz="0" izz="0.00020935"/>
      </inertial> 
  </link> 

  <joint name="base_to_L11_wheel" type="continuous">
      <parent link="base_link"/>
      <child link="L11"/> 
      <axis xyz="0 1 0"/>
      <!-- Add 1/2 wheel thickness + 7 mm for the y offset-->
      <!-- Add the (685 mm) track length/2 - wheel radius for the maximal x offset-->
      <!-- Subtract the position of the wheel base above ground (39.5 mm) from wheel radius for the z offset-->
      <origin xyz="0.2605 -0.1721 0.0125"/>
  </joint>

  <link name="L11">
      <visual> 
          <geometry> 
              <cylinder length="0.0762" radius="0.082"/>
          </geometry>
          <origin rpy="1.57075 0 0"/>
          <material name="White"/>
      </visual>
      <collision> 
            <geometry> 
              <cylinder length="0.0762" radius="0.082"/>
          </geometry>
          <origin rpy="1.57075 0 0"/>
      </collision> 
      <inertial> 
          <origin rpy="1.57075 0 0"/>
          <mass value="0.06227"/>
          <inertia ixx="0.0001348" ixy="0" ixz="0" iyy="0.0001348" iyz="0" izz="0.00020935"/>
      </inertial> 
  </link> 
  
  <!-- Right Track -->

  <joint name="base_to_R1_wheel" type="continuous">
        <parent link="base_link"/>
        <child link="R1"/> 
        <axis xyz="0 1 0"/>
        <!-- Add 1/2 wheel thickness + 7 mm for the y offset-->
        <!-- Add the (685 mm) track length/2 - wheel radius for the maximal x offset-->
        <!-- Subtract the position of the wheel base above ground (39.5 mm) from wheel radius for the z offset-->
        <origin xyz="-0.2605 0.1721 0.0125"/>
  </joint>

  <link name="R1">
      <visual> 
          <geometry> 
              <cylinder length="0.0762" radius="0.082"/>
          </geometry>
          <origin rpy="1.57075 0 0"/>
          <material name="White"/>
      </visual>
      <collision> 
            <geometry> 
              <cylinder length="0.0762" radius="0.082"/>
          </geometry>
          <origin rpy="1.57075 0 0"/>
      </collision> 
      <inertial> 
          <origin rpy="1.57075 0 0"/>
          <mass value="0.06227"/>
          <inertia ixx="0.0001348" ixy="0" ixz="0" iyy="0.0001348" iyz="0" izz="0.00020935"/>
      </inertial> 
  </link> 
  
  <joint name="base_to_R2_wheel" type="continuous">
        <parent link="base_link"/>
        <child link="R2"/> 
        <axis xyz="0 1 0"/>
        <origin xyz="-0.2084 0.1721 0.0125"/>
  </joint>

  <link name="R2">
      <visual> 
          <geometry> 
              <cylinder length="0.0762" radius="0.082"/>
          </geometry>
          <origin rpy="1.57075 0 0"/>
          <material name="White"/>
      </visual>
      <collision> 
            <geometry> 
              <cylinder length="0.0762" radius="0.082"/>
          </geometry>
          <origin rpy="1.57075 0 0"/>
      </collision> 
      <inertial> 
          <origin rpy="1.57075 0 0"/>
          <mass value="0.06227"/>
          <inertia ixx="0.0001348" ixy="0" ixz="0" iyy="0.0001348" iyz="0" izz="0.00020935"/>
      </inertial> 
  </link> 

  <joint name="base_to_R3_wheel" type="continuous">
        <parent link="base_link"/>
        <child link="R3"/> 
        <axis xyz="0 1 0"/>
        <origin xyz="-0.1563 0.1721 0.0125"/>
  </joint>

  <link name="R3">
      <visual> 
          <geometry> 
              <cylinder length="0.0762" radius="0.082"/>
          </geometry>
          <origin rpy="1.57075 0 0"/>
          <material name="White"/>
      </visual>
      <collision> 
            <geometry> 
              <cylinder length="0.0762" radius="0.082"/>
          </geometry>
          <origin rpy="1.57075 0 0"/>
      </collision> 
      <inertial> 
          <origin rpy="1.57075 0 0"/>
          <mass value="0.06227"/>
          <inertia ixx="0.0001348" ixy="0" ixz="0" iyy="0.0001348" iyz="0" izz="0.00020935"/>
      </inertial> 
  </link> 
  
  <joint name="base_to_R4_wheel" type="continuous">
        <parent link="base_link"/>
        <child link="R4"/> 
        <axis xyz="0 1 0"/>
        <origin xyz="-0.1042 0.1721 0.0125"/>
  </joint>

  <link name="R4">
      <visual> 
          <geometry> 
              <cylinder length="0.0762" radius="0.082"/>
          </geometry>
          <origin rpy="1.57075 0 0"/>
          <material name="White"/>
      </visual>
      <collision> 
            <geometry> 
              <cylinder length="0.0762" radius="0.082"/>
          </geometry>
          <origin rpy="1.57075 0 0"/>
      </collision> 
      <inertial> 
          <origin rpy="1.57075 0 0"/>
          <mass value="0.06227"/>
          <inertia ixx="0.0001348" ixy="0" ixz="0" iyy="0.0001348" iyz="0" izz="0.00020935"/>
      </inertial> 
  </link> 

  <joint name="base_to_R5_wheel" type="continuous">
        <parent link="base_link"/>
        <child link="R5"/> 
        <axis xyz="0 1 0"/>
        <origin xyz="-0.0521 0.1721 0.0125"/>
  </joint>

  <link name="R5">
      <visual> 
          <geometry> 
              <cylinder length="0.0762" radius="0.082"/>
          </geometry>
          <origin rpy="1.57075 0 0"/>
          <material name="White"/>
      </visual>
      <collision> 
            <geometry> 
              <cylinder length="0.0762" radius="0.082"/>
          </geometry>
          <origin rpy="1.57075 0 0"/>
      </collision> 
      <inertial> 
          <origin rpy="1.57075 0 0"/>
          <mass value="0.06227"/>
          <inertia ixx="0.0001348" ixy="0" ixz="0" iyy="0.0001348" iyz="0" izz="0.00020935"/>
      </inertial> 
  </link> 

  <joint name="base_to_R6_wheel" type="continuous">
        <parent link="base_link"/>
        <child link="R6"/> 
        <axis xyz="0 1 0"/>
        <origin xyz="0 0.1721 0.0125"/>
  </joint>

  <link name="R6">
      <visual> 
          <geometry> 
              <cylinder length="0.0762" radius="0.082"/>
          </geometry>
          <origin rpy="1.57075 0 0"/>
          <material name="White"/>
      </visual>
      <collision> 
            <geometry> 
              <cylinder length="0.0762" radius="0.082"/>
          </geometry>
          <origin rpy="1.57075 0 0"/>
      </collision> 
      <inertial> 
          <origin rpy="1.57075 0 0"/>
          <mass value="0.06227"/>
          <inertia ixx="0.0001348" ixy="0" ixz="0" iyy="0.0001348" iyz="0" izz="0.00020935"/>
      </inertial> 
  </link> 

  <joint name="base_to_R7_wheel" type="continuous">
        <parent link="base_link"/>
        <child link="R7"/> 
        <axis xyz="0 1 0"/>
        <origin xyz="0.0521 0.1721 0.0125"/>
  </joint>

  <link name="R7">
      <visual> 
          <geometry> 
              <cylinder length="0.0762" radius="0.082"/>
          </geometry>
          <origin rpy="1.57075 0 0"/>
          <material name="White"/>
      </visual>
      <collision> 
            <geometry> 
              <cylinder length="0.0762" radius="0.082"/>
          </geometry>
          <origin rpy="1.57075 0 0"/>
      </collision> 
      <inertial> 
          <origin rpy="1.57075 0 0"/>
          <mass value="0.06227"/>
          <inertia ixx="0.0001348" ixy="0" ixz="0" iyy="0.0001348" iyz="0" izz="0.00020935"/>
      </inertial> 
  </link> 

  <joint name="base_to_R8_wheel" type="continuous">
        <parent link="base_link"/>
        <child link="R8"/> 
        <axis xyz="0 1 0"/>
        <origin xyz="0.1042 0.1721 0.0125"/>
  </joint>

  <link name="R8">
      <visual> 
          <geometry> 
              <cylinder length="0.0762" radius="0.082"/>
          </geometry>
          <origin rpy="1.57075 0 0"/>
          <material name="White"/>
      </visual>
      <collision> 
            <geometry> 
              <cylinder length="0.0762" radius="0.082"/>
          </geometry>
          <origin rpy="1.57075 0 0"/>
      </collision> 
      <inertial> 
          <origin rpy="1.57075 0 0"/>
          <mass value="0.06227"/>
          <inertia ixx="0.0001348" ixy="0" ixz="0" iyy="0.0001348" iyz="0" izz="0.00020935"/>
      </inertial> 
  </link> 

  <joint name="base_to_R9_wheel" type="continuous">
        <parent link="base_link"/>
        <child link="R9"/> 
        <axis xyz="0 1 0"/>
        <origin xyz="0.1563 0.1721 0.0125"/>
  </joint>

  <link name="R9">
      <visual> 
          <geometry> 
              <cylinder length="0.0762" radius="0.082"/>
          </geometry>
          <origin rpy="1.57075 0 0"/>
          <material name="White"/>
      </visual>
      <collision> 
            <geometry> 
              <cylinder length="0.0762" radius="0.082"/>
          </geometry>
          <origin rpy="1.57075 0 0"/>
      </collision> 
      <inertial> 
          <origin rpy="1.57075 0 0"/>
          <mass value="0.06227"/>
          <inertia ixx="0.0001348" ixy="0" ixz="0" iyy="0.0001348" iyz="0" izz="0.00020935"/>
      </inertial> 
  </link> 

  <joint name="base_to_R10_wheel" type="continuous">
        <parent link="base_link"/>
        <child link="R10"/> 
        <axis xyz="0 1 0"/>
        <origin xyz="0.2084 0.1721 0.0125"/>
  </joint>

  <link name="R10">
      <visual> 
          <geometry> 
              <cylinder length="0.0762" radius="0.082"/>
          </geometry>
          <origin rpy="1.57075 0 0"/>
          <material name="White"/>
      </visual>
      <collision> 
            <geometry> 
              <cylinder length="0.0762" radius="0.082"/>
          </geometry>
          <origin rpy="1.57075 0 0"/>
      </collision> 
      <inertial> 
          <origin rpy="1.57075 0 0"/>
          <mass value="0.06227"/>
          <inertia ixx="0.0001348" ixy="0" ixz="0" iyy="0.0001348" iyz="0" izz="0.00020935"/>
      </inertial> 
  </link> 

  <joint name="base_to_R11_wheel" type="continuous">
      <parent link="base_link"/>
      <child link="R11"/> 
      <axis xyz="0 1 0"/>
      <!-- Add 1/2 wheel thickness + 7 mm for the y offset-->
      <!-- Add the (685 mm) track length/2 - wheel radius for the maximal x offset-->
      <!-- Subtract the position of the wheel base above ground (39.5 mm) from wheel radius for the z offset-->
      <origin xyz="0.2605 0.1721 0.0125"/>
  </joint>

  <link name="R11">
      <visual> 
          <geometry> 
              <cylinder length="0.0762" radius="0.082"/>
          </geometry>
          <origin rpy="1.57075 0 0"/>
          <material name="White"/>
      </visual>
      <collision> 
            <geometry> 
              <cylinder length="0.0762" radius="0.082"/>
          </geometry>
          <origin rpy="1.57075 0 0"/>
      </collision> 
      <inertial> 
          <origin rpy="1.57075 0 0"/>
          <mass value="0.06227"/>
          <inertia ixx="0.0001348" ixy="0" ixz="0" iyy="0.0001348" iyz="0" izz="0.00020935"/>
      </inertial> 
  </link> 
    
  <!-- FLIPPERS -->

  <!-- FRONT LEFT FLIPPER-->

  <joint name="base_to_LF_flipper" type="revolute">
    <parent link="base_link"/>
    <child link="LF_flipper_main"/>
    <limit effort="30.0" lower="-1.57079632679" upper="1.57079632679" velocity="7.0"/>
    <!--Add the wheel thickness and the half width of the flipper and 7 mm to get the y offset-->
      <origin xyz="0.2605 -0.2418 0.0125"/>
    <axis xyz="0 1 0"/>
    <dynamics damping="0.0"/>
  </joint>

  <link name="LF_flipper_main">
    <visual>
      <geometry>
        <mesh filename="gvrbot_step_files/flipper.stl" scale="0.001 0.001 0.001"/>
      </geometry>
      <origin rpy="0 0 1.57075" xyz="0 0 0"/>
      <material name="Blue" />
    </visual>
    <collision>
      <geometry>
        <mesh filename="gvrbot_step_files/flipper.stl" scale="0.001 0.001 0.001"/>
      </geometry>
      <origin rpy="0 0 1.57075" xyz="0 0 0"/>
    </collision>
    <inertial>
        <mass value="1.026" />
        <origin rpy="0 0 0" xyz="0.03 0 0 " />
        <inertia ixx="0.000926" ixy="0" ixz="0" iyy="0.001459" iyz="0" izz="0.00825" />
      </inertial>
  </link>
 
  <!-- FRONT RIGHT FLIPPER-->

  <joint name="base_to_RF_flipper" type="revolute">
      <parent link="base_link"/>
      <child link="RF_flipper_main"/>
      <limit effort="30.0" lower="-1.57079632679" upper="1.57079632679" velocity="7.0"/>
      <origin xyz="0.2605 0.2418 0.0125"/>
      <axis xyz="0 1 0"/>
      <dynamics damping="0.0"/>
  </joint>

  <link name="RF_flipper_main">
    <visual>
      <geometry>
        <mesh filename="gvrbot_step_files/flipper.stl" scale="0.001 0.001 0.001"/>
      </geometry>
      <origin rpy="0 0 1.57075" xyz="0 0 0"/>
      <material name="Blue" />
    </visual>
    <collision>
      <geometry>
        <mesh filename="gvrbot_step_files/flipper.stl" scale="0.001 0.001 0.001"/>
      </geometry>
      <origin rpy="0 0 1.57075" xyz="0 0 0"/>
    </collision>
    <inertial>
        <mass value="1.026" />
        <origin rpy="0 0 0" xyz="0.03 0 0" />
        <inertia ixx="0.000926" ixy="0" ixz="0" iyy="0.001459" iyz="0" izz="0.00825" />
      </inertial>
  </link>
  <!-- PAYLOAD-->
  

 
</robot>
