<?xml version="1.0" ?>
<!-- =================================================================================== -->
<!-- |    This document was autogenerated by xacro from urdf/tracked.xacro               | -->
<!-- |    EDITING THIS FILE BY HAND IS NOT RECOMMENDED                                 | -->
<!-- =================================================================================== -->
<robot name="wheeled_flipper" xmlns:xacro="http://www.ros.org/wiki/xacro">
  <!-- <xacro:include filename="$(find pexod_description)/urdf/pexod_control.xacro" /> -->
  <!-- MATERIALS -->
  <material name="Blue">
    <color rgba="0 0 1 1"/>
  </material>
  <material name="Red">
    <color rgba="1 0 0 1"/>
  </material>
  <material name="Green">
    <color rgba="0 1 0 1"/>
  </material>
  <material name="Yellow">
    <color rgba="1 1 0 1"/>
  </material>
  <material name="Orange">
    <color rgba="1 0.5 0 1"/>
  </material>
  <material name="LightGrey">
    <color rgba="0.6 0.6 0.6 1.0"/>
  </material>
  <material name="White">
    <color rgba="0 0 0 0"/>
  </material>

  <!-- END OF MATERIALS -->
  <!-- XACRO MACROS FOR VISUALS AND COLLISIONS -->
  <!-- END OF XACRO MACROS -->

  <!-- TORSO -->
  <link name="base_link">
    <visual>
      <origin rpy="0 0 0" xyz="0 0 0"/>
      <geometry>
        <box size="0.68 0.405 0.18"/>
      </geometry>
      <material name="Black"/>
    </visual>
    <collision>
      <origin rpy="0 0 0" xyz="0 0 0"/>
      <geometry>
        <box size="0.68 0.405 0.18"/>
      </geometry>
    </collision>
    <inertial>
      <!-- CENTER OF MASS -->
      <origin rpy="0 0 0" xyz="0 0 -0.08"/>
      <mass value="10"/>
      <inertia ixx="0.24553" ixy="0" ixz="0" iyy="0.6185" iyz="0" izz="0.783"/>
    </inertial>
  </link>

  <!-- LINKS/JOINTS -->

  <!-- WHEEELS-->

  <!-- Left Front Wheel -->

  <joint name="base_to_LF_wheel" type="continuous">
        <parent link="base_link"/>
        <child link="LF_wheel"/> 
        <axis xyz="0 1 0"/>
        <origin xyz="-0.3 -0.2525 0"/>
    </joint>

    <link name="LF_wheel">
        <visual> 
            <geometry> 
                <cylinder length="0.1" radius="0.1"/>
            </geometry>
            <origin rpy="1.57075 1.57075 0"/>
            <material name="Blue"/>
        </visual>
        <collision> 
             <geometry> 
                <cylinder length="0.1" radius="0.1"/>
            </geometry>
            <origin rpy="1.57075 1.57075 0"/>
        </collision> 
        <inertial> 
            <origin rpy="1.57075 1.57075 0"/>
            <mass value="1"/>
            <inertia ixx="0.010833" ixy="0" ixz="0" iyy="0.010833" iyz="0" izz="0.02"/>
        </inertial> 
    </link> 
    
  <!-- Right Front Wheel -->
  
  <joint name="base_to_RF_wheel" type="continuous">
        <parent link="base_link"/>
        <child link="RF_wheel"/> 
        <axis xyz="0 1 0"/>
        <origin xyz="-0.3 0.2525 0"/>
    </joint>

    <link name="RF_wheel">
        <visual> 
            <geometry> 
                <cylinder length="0.1" radius="0.1"/>
            </geometry>
            <origin rpy="1.57075 1.57075 0"/>
            <material name="Blue"/>
        </visual>
        <collision> 
             <geometry> 
                <cylinder length="0.1" radius="0.1"/>
            </geometry>
            <origin rpy="1.57075 1.57075 0"/>
        </collision> 
        <inertial> 
            <origin rpy="1.57075 1.57075 0"/>
            <mass value="1"/>
            <inertia ixx="0.010833" ixy="0" ixz="0" iyy="0.010833" iyz="0" izz="0.02"/>
        </inertial> 
    </link> 
    

  <!-- Left Back Wheel -->

     <joint name="base_to_LB_wheel" type="continuous">
        <parent link="base_link"/>
        <child link="LB_wheel"/> 
        <axis xyz="0 1 0"/>
        <origin xyz="0.3 -0.2525 0"/>
    </joint>
    
    <link name="LB_wheel">
        <visual> 
            <geometry> 
                <cylinder length="0.1" radius="0.1"/>
            </geometry>
            <origin rpy="1.57075 1.57075 0"/>
            <material name="Blue"/>
        </visual>
        <collision> 
             <geometry> 
                <cylinder length="0.1" radius="0.1"/>
            </geometry>
            <origin rpy="1.57075 1.57075 0"/>
        </collision> 
        <inertial> 
            <origin rpy="1.57075 1.57075 0"/>
            <mass value="1"/>
            <inertia ixx="0.010833" ixy="0" ixz="0" iyy="0.010833" iyz="0" izz="0.02"/>
        </inertial> 
    </link> 

    <!-- Right Back Wheel -->

    <joint name="base_to_RB_wheel" type="continuous">
        <parent link="base_link"/>
        <child link="RB_wheel"/> 
        <axis xyz="0 1 0"/>
        <origin xyz="0.3 0.2525 0"/>
    </joint>
        
    <link name="RB_wheel">
        <visual> 
            <geometry> 
                <cylinder length="0.1" radius="0.1"/>
            </geometry>
            <origin rpy="1.57075 1.57075 0"/>
            <material name="Blue"/>
        </visual>
        <collision> 
             <geometry> 
                <cylinder length="0.1" radius="0.1"/>
            </geometry>
            <origin rpy="1.57075 1.57075 0"/>
        </collision> 
        <inertial> 
            <origin rpy="1.57075 1.57075 0"/>
            <mass value="1"/>
            <inertia ixx="0.010833" ixy="0" ixz="0" iyy="0.010833" iyz="0" izz="0.02"/>
        </inertial> 
    </link> 
    
  <!-- FLIPPERS -->

  <!-- FRONT LEFT FLIPPER-->

  <joint name="base_to_LF_flipper" type="revolute">
    <parent link="base_link"/>
    <child link="LF_flipper_main"/>
    <limit effort="30.0" lower="-1.57079632679" upper="1.57079632679" velocity="7.0"/>
    <origin rpy="0 0 0" xyz="0.35 -0.3525 0"/>
    <axis xyz="0 1 0"/>
    <dynamics damping="0.0"/>
  </joint>
  
    <link name="LF_flipper_main">
    <visual>
      <origin rpy="0 0 0" xyz="0.12 0. 0."/> 
      <geometry>
        <box size="0.3 0.1 0.1"/>
      </geometry>
      <material name="Red"/>
    </visual>

    <collision>
      <origin rpy="0 0 0" xyz="0.12 0. 0."/> 
      <geometry>
        <box size="0.3 0.1 0.1"/>
      </geometry>
    </collision>000

    <inertial>
      <!-- CENTER OF MASS -->
      <origin rpy="0 0 0" xyz="0.0 0.0 0.0"/>
      <mass value=".5"/>
      <inertia ixx="0.00020833" ixy="0" ixz="0" iyy="0.001770833" iyz="0" izz="0.001770833"/>
    </inertial>
  </link>

  <joint name="LF_flipper_to_end" type="fixed">
    <parent link="LF_flipper_main"/>
    <child link="LF_flipper_end"/>
    <origin rpy="0 0 0" xyz="0.3 0 0"/>
    <axis xyz="0 1 0"/>
  </joint>

  <link name="LF_flipper_end">
    <visual>
      <origin rpy="1.5708 0 0" xyz="0 0. 0."/> 
      <geometry>
        <cylinder length="0.1" radius="0.055"/>
      </geometry>
      <material name="Orange"/>
    </visual>

    <collision>
      <origin rpy="1.5708 0 0" xyz="0 0. 0."/> 
      <geometry>
        <cylinder length="0.1" radius="0.055"/>
      </geometry>
    </collision>

    <inertial>
      <origin rpy="0 0 0" xyz="0.0 0.0 0.0"/>
      <mass value=".1"/>
      <inertia ixx="0.0000497" ixy="0" ixz="0" iyy="0.0000497" iyz="0" izz="0.0000578"/>
    </inertial>
  </link>

  <!-- BACK LEFT FLIPPER-->

  <joint name="base_to_LB_flipper" type="revolute">
    <parent link="base_link"/>
    <child link="LB_flipper_main"/>
    <limit effort="30.0" lower="-1.57079632679" upper="1.57079632679" velocity="7.0"/>
    <origin rpy="0 0 0" xyz="-0.35 -0.3525 0"/>
    <axis xyz="0 1 0"/>
    <dynamics damping="0.0"/>
  </joint>

  <link name="LB_flipper_main">
    <visual>
      <origin rpy="0 0 0" xyz="-0.12 0. 0."/> 
      <geometry>
        <box size="0.3 0.1 0.1"/>
      </geometry>
      <material name="Red"/>
    </visual>

    <collision>
      <origin rpy="0 0 0" xyz="-0.12 0. 0."/> 
      <geometry>
        <box size="0.3 0.1 0.1"/>
      </geometry>
    </collision>

    <inertial>
      <!-- CENTER OF MASS -->
      <origin rpy="0 0 0" xyz="0.0 0.0 0.0"/>
      <mass value=".5"/>
      <inertia ixx="0.00020833" ixy="0" ixz="0" iyy="0.001770833" iyz="0" izz="0.001770833"/>
    </inertial>
  </link>


  <joint name="LB_flipper_to_end" type="fixed">
    <parent link="LB_flipper_main"/>
    <child link="LB_flipper_end"/>
    <origin rpy="0 0 0" xyz="-0.3 0 0"/>
    <axis xyz="0 1 0"/>
  </joint>

  <link name="LB_flipper_end">
    <visual>
      <origin rpy="1.5708 0 0" xyz="0 0. 0."/> 
      <geometry>
        <cylinder length="0.1" radius="0.055"/>
      </geometry>
      <material name="Orange"/>
    </visual>

    <collision>
      <origin rpy="1.5708 0 0" xyz="0 0. 0."/> 
      <geometry>
        <cylinder length="0.1" radius="0.055"/>
      </geometry>
    </collision>

    <inertial>
      <origin rpy="0 0 0" xyz="0.0 0.0 0.0"/>
      <mass value=".1"/>
      <inertia ixx="0.0000497" ixy="0" ixz="0" iyy="0.0000497" iyz="0" izz="0.0000578"/>
    </inertial>
  </link>

    <!-- FRONT RIGHT FLIPPER-->

    <joint name="base_to_RF_flipper" type="revolute">
        <parent link="base_link"/>
        <child link="RF_flipper_main"/>
        <limit effort="30.0" lower="-1.57079632679" upper="1.57079632679" velocity="7.0"/>
        <origin rpy="0 0 0" xyz="0.35 0.3525 0"/>
        <axis xyz="0 1 0"/>
        <dynamics damping="0.0"/>
    </joint>

   <link name="RF_flipper_main">
    <visual>
      <origin rpy="0 0 0" xyz="0.12 0. 0."/> 
      <geometry>
        <box size="0.3 0.1 0.1"/>
      </geometry>
      <material name="Red"/>
    </visual>

    <collision>
      <origin rpy="0 0 0" xyz="0.12 0. 0."/> 
      <geometry>
        <box size="0.3 0.1 0.1"/>
      </geometry>
    </collision>

    <inertial>
      <!-- CENTER OF MASS -->
      <origin rpy="0 0 0" xyz="0.0 0.0 0.0"/>
      <mass value=".5"/>
      <inertia ixx="0.00020833" ixy="0" ixz="0" iyy="0.001770833" iyz="0" izz="0.001770833"/>
    </inertial>
  </link>

  <joint name="RF_flipper_to_end" type="fixed">
    <parent link="RF_flipper_main"/>
    <child link="RF_flipper_end"/>
    <origin rpy="0 0 0" xyz="0.3 0 0"/>
    <axis xyz="0 1 0"/>
  </joint>

  <link name="RF_flipper_end">
    <visual>
      <origin rpy="1.5708 0 0" xyz="0 0. 0."/> 
      <geometry>
        <cylinder length="0.1" radius="0.055"/>
      </geometry>
      <material name="Orange"/>
    </visual>

    <collision>
      <origin rpy="1.5708 0 0" xyz="0 0. 0."/> 
      <geometry>
        <cylinder length="0.1" radius="0.055"/>
      </geometry>
    </collision>

    <inertial>
      <origin rpy="0 0 0" xyz="0.0 0.0 0.0"/>
      <mass value=".1"/>
      <inertia ixx="0.0000497" ixy="0" ixz="0" iyy="0.0000497" iyz="0" izz="0.0000578"/>
    </inertial>
  </link>

    <!-- BACK RIGHT FLIPPER-->

  <joint name="base_to_RB_flipper" type="revolute">
    <parent link="base_link"/>
    <child link="RB_flipper_main"/>
    <limit effort="30.0" lower="-1.57079632679" upper="1.57079632679" velocity="7.0"/>
    <origin rpy="0 0.0 0" xyz="-0.35 0.3525 -0"/>
    <axis xyz="0 1 0"/>   <!-- Colors --> 
    <material name="grey"> 
        <color rgba="0.91 0.925 0.945 1"/>
    </material>
    <dynamics damping="0.0"/>
  </joint>

  <link name="RB_flipper_main">
    <visual>
      <origin rpy="0 0 0" xyz="-0.12 0. 0."/> 
      <geometry>
        <box size="0.3 0.1 0.1"/>
      </geometry>
      <material name="Red"/>
    </visual>

    <collision>
      <origin rpy="0 0 0" xyz="-0.12 0. 0."/> 
      <geometry>
        <box size="0.3 0.1 0.1"/>
      </geometry>
    </collision>

    <inertial>
      <!-- CENTER OF MASS -->
      <origin rpy="0 0 0" xyz="0.0 0.0 0.0"/>
      <mass value=".5"/>
      <inertia ixx="0.00020833" ixy="0" ixz="0" iyy="0.001770833" iyz="0" izz="0.001770833"/>
    </inertial>
  </link>

  <joint name="RB_flipper_to_end" type="fixed">
    <parent link="RB_flipper_main"/>
    <child link="RB_flipper_end"/>
    <origin rpy="0 0 0" xyz="-0.3 0 0"/>
    <axis xyz="0 1 0"/>
  </joint>

  <link name="RB_flipper_end">
    <visual>
      <origin rpy="1.5708 0 0" xyz="0 0. 0."/> 
      <geometry>
        <cylinder length="0.1" radius="0.055"/>
      </geometry>
      <material name="Orange"/>
    </visual>

    <collision>
      <origin rpy="1.5708 0 0" xyz="0 0. 0."/> 
      <geometry>
        <cylinder length="0.1" radius="0.055"/>
      </geometry>
    </collision>

    <inertial>
      <origin rpy="0 0 0" xyz="0.0 0.0 0.0"/>
      <mass value=".1"/>
      <inertia ixx="0.0000497" ixy="0" ixz="0" iyy="0.0000497" iyz="0" izz="0.0000578"/>
    </inertial>
  </link>

  <!-- PAYLOAD-->
  

 
</robot>
