<?xml version="1.0" ?>
<!-- =================================================================================== -->
<!-- |    This document was autogenerated by xacro from urdf/tracked.xacro               | -->
<!-- |    EDITING THIS FILE BY HAND IS NOT RECOMMENDED                                 | -->
<!-- =================================================================================== -->
<robot name="gvrbot_updated" xmlns:xacro="http://www.ros.org/wiki/xacro">
  <!-- <xacro:include filename="$(find pexod_description)/urdf/pexod_control.xacro" /> -->
  <!-- MATERIALS -->
  <material name="Blue">
    <color rgba="0 0 1 1"/>
  </material>
  <material name="Red">
    <color rgba="1 0 0 1"/>
  </material>
  <material name="Green">
    <color rgba="0 1 0 1"/>
  </material>
  <material name="Yellow">
    <color rgba="1 1 0 1"/>
  </material>
  <material name="Orange">
    <color rgba="1 0.5 0 1"/>
  </material>
  <material name="LightGrey">
    <color rgba="0.6 0.6 0.6 1.0"/>
  </material>
  <material name="White">
    <color rgba="1 1 1 1"/>
  </material>

  <!-- END OF MATERIALS -->
  <!-- XACRO MACROS FOR VISUALS AND COLLISIONS -->
  <!-- END OF XACRO MACROS -->

  <!-- TORSO -->
  <link name="base_link">
    <!--
    <visual>
      <origin rpy="0 0 0" xyz="0 0 0"/>
      <geometry>
        <box size="0.588 0.254 0.06"/>
      </geometry>
      <material name="Black"/>
    </visual>
    -->
    
    <visual>
      <origin rpy="0 0 3.14159" xyz="0 0 0"/>
      <geometry>
        <mesh filename="Base_Centered_Stripped.obj" scale="1.0 1.0 1.0" />
      </geometry>
    </visual>
    
    <collision>
      <origin rpy="0 0 0" xyz="0 0 0"/>
      <geometry>
        <box size="0.588 0.254 0.06"/>
      </geometry>
    </collision>

    <inertial>
      <!-- CENTER OF MASS -->
      <origin rpy="0 0 0" xyz="0.01847 0.0292 -0.007"/>
      <mass value="16.4"/>
      <!-- moments of inertia around the COM in the output frame of reference --> 
      <!-- must negate the products of inertia from CAD output (see wiki.ros.org/urdf/XML/link for details)-->
      <inertia ixx="0.267" ixy="0.008646" ixz="-0.0140668" iyy="0.4712" iyz="0.00285" izz="0.668"/>
    </inertial>
  </link>

  <!-- CENTER OF MASS SHIFTING BLOCK-->

  <joint name="box_link" type="fixed">
      <parent link="base_link"/>
      <child link="box"/>
      <origin xyz="0 0 0.3"/>
  </joint>

  <link name="box">
    <visual>
      <origin rpy="0 0 0" xyz="0 0 0"/>
      <geometry>
        <box size="0.1 0.1 0.1"/>
      </geometry>
      <material name="Black"/>
    </visual>

    <inertial>
      <origin rpy="0 0 0" xyz="0 0 0"/>
      <mass value="0"/>
      <inertia ixx="0.0" ixy="0.0" ixz="0.0" iyy="0.0" iyz="0.0" izz="00"/>
    </inertial>
  </link>

  <!-- LINKS/JOINTS -->

  <!-- WHEEELS-->

  <!-- Left Track -->

  <joint name="base_to_L1_wheel" type="continuous">
        <parent link="base_link"/>
        <child link="L1"/> 
        <axis xyz="0 1 0"/>
        <!-- Divide total wheel mass (0.685 kg/track) / num_wheel (11) -->
        <!-- Add 1/2 wheel thickness + 7 mm for the y offset-->
        <!-- Add the (685 mm) track length/2 - wheel radius for the maximal x offset-->
        <!-- Subtract the position of the wheel base above ground (39.5 mm) from wheel radius for the z offset-->
        <origin xyz="-0.2605 -0.1721 0.0125"/>
  </joint>

  <link name="L1">
      <contact>
        <stiffness value="30000"/>
        <damping value="10000"/>        
        <lateral_friction value="0.1"/>
      </contact>
      <visual> 
          <geometry> 
              <cylinder length="0.0762" radius="0.082"/>
          </geometry>
          <origin rpy="1.57075 0 0"/>
          <material name="White"/>
      </visual>
      <collision> 
            <geometry> 
              <cylinder length="0.0762" radius="0.082"/>
          </geometry>
          <origin rpy="1.57075 0 0"/>
      </collision> 
      <inertial> 
          <origin rpy="1.57075 0 0"/>
          <mass value="0.12455"/>
          <inertia ixx="0.0002693" ixy="0" ixz="0" iyy="0.0002693" iyz="0" izz="0.0004187"/>
      </inertial> 
  </link> 

  <joint name="base_to_L2_wheel" type="continuous">
        <parent link="base_link"/>
        <child link="L2"/> 
        <axis xyz="0 1 0"/>
        <origin xyz="-0.2084 -0.1721 0.0125"/>
  </joint>

  <link name="L2">
      <contact>
        <stiffness value="30000"/>
        <damping value="10000"/>        
        <lateral_friction value="0.1"/>
      </contact>
      <visual> 
          <geometry> 
              <cylinder length="0.0762" radius="0.082"/>
          </geometry>
          <origin rpy="1.57075 0 0"/>
          <material name="White"/>
      </visual>
      <collision> 
            <geometry> 
              <cylinder length="0.0762" radius="0.082"/>
          </geometry>
          <origin rpy="1.57075 0 0"/>
      </collision> 
      <inertial> 
          <origin rpy="1.57075 0 0"/>
          <mass value="0.12455"/>
          <inertia ixx="0.0002693" ixy="0" ixz="0" iyy="0.0002693" iyz="0" izz="0.0004187"/>
      </inertial> 
  </link> 

  <joint name="base_to_L3_wheel" type="continuous">
        <parent link="base_link"/>
        <child link="L3"/> 
        <axis xyz="0 1 0"/>
        <origin xyz="-0.1563 -0.1721 0.0125"/>
  </joint>

  <link name="L3">
      <contact>
        <stiffness value="30000"/>
        <damping value="10000"/>        
        <lateral_friction value="0.1"/>
      </contact>
      <visual> 
          <geometry> 
              <cylinder length="0.0762" radius="0.082"/>
          </geometry>
          <origin rpy="1.57075 0 0"/>
          <material name="White"/>
      </visual>
      <collision> 
            <geometry> 
              <cylinder length="0.0762" radius="0.082"/>
          </geometry>
          <origin rpy="1.57075 0 0"/>
      </collision> 
      <inertial> 
          <origin rpy="1.57075 0 0"/>
          <mass value="0.12455"/>
          <inertia ixx="0.0002693" ixy="0" ixz="0" iyy="0.0002693" iyz="0" izz="0.0004187"/>
      </inertial> 
  </link> 
  
  <joint name="base_to_L4_wheel" type="continuous">
        <parent link="base_link"/>
        <child link="L4"/> 
        <axis xyz="0 1 0"/>
        <origin xyz="-0.1042 -0.1721 0.0125"/>
  </joint>

  <link name="L4">
      <contact>
        <stiffness value="30000"/>
        <damping value="10000"/>        
        <lateral_friction value="0.1"/>
      </contact>
      <visual> 
          <geometry> 
              <cylinder length="0.0762" radius="0.082"/>
          </geometry>
          <origin rpy="1.57075 0 0"/>
          <material name="White"/>
      </visual>
      <collision> 
            <geometry> 
              <cylinder length="0.0762" radius="0.082"/>
          </geometry>
          <origin rpy="1.57075 0 0"/>
      </collision> 
      <inertial> 
          <origin rpy="1.57075 0 0"/>
          <mass value="0.12455"/>
          <inertia ixx="0.0002693" ixy="0" ixz="0" iyy="0.0002693" iyz="0" izz="0.0004187"/>
      </inertial> 
  </link> 

  <joint name="base_to_L5_wheel" type="continuous">
        <parent link="base_link"/>
        <child link="L5"/> 
        <axis xyz="0 1 0"/>
        <origin xyz="-0.0521 -0.1721 0.0125"/>
  </joint>

  <link name="L5">
      <contact>
        <stiffness value="30000"/>
        <damping value="10000"/>        
        <lateral_friction value="0.1"/>
      </contact>
      <visual> 
          <geometry> 
              <cylinder length="0.0762" radius="0.082"/>
          </geometry>
          <origin rpy="1.57075 0 0"/>
          <material name="White"/>
      </visual>
      <collision> 
            <geometry> 
              <cylinder length="0.0762" radius="0.082"/>
          </geometry>
          <origin rpy="1.57075 0 0"/>
      </collision> 
      <inertial> 
          <origin rpy="1.57075 0 0"/>
          <mass value="0.12455"/>
          <inertia ixx="0.0002693" ixy="0" ixz="0" iyy="0.0002693" iyz="0" izz="0.0004187"/>
      </inertial> 
  </link> 

  <joint name="base_to_L6_wheel" type="continuous">
        <parent link="base_link"/>
        <child link="L6"/> 
        <axis xyz="0 1 0"/>
        <origin xyz="0 -0.1721 0.0125"/>
  </joint>

  <link name="L6">
      <contact>
        <stiffness value="30000"/>
        <damping value="10000"/>        
        <lateral_friction value="0.1"/>
      </contact>
      <visual> 
          <geometry> 
              <cylinder length="0.0762" radius="0.082"/>
          </geometry>
          <origin rpy="1.57075 0 0"/>
          <material name="White"/>
      </visual>
      <collision> 
            <geometry> 
              <cylinder length="0.0762" radius="0.082"/>
          </geometry>
          <origin rpy="1.57075 0 0"/>
      </collision> 
      <inertial> 
          <origin rpy="1.57075 0 0"/>
          <mass value="0.12455"/>
          <inertia ixx="0.0002693" ixy="0" ixz="0" iyy="0.0002693" iyz="0" izz="0.0004187"/>
      </inertial> 
  </link> 

  <joint name="base_to_L7_wheel" type="continuous">
        <parent link="base_link"/>
        <child link="L7"/> 
        <axis xyz="0 1 0"/>
        <origin xyz="0.0521 -0.1721 0.0125"/>
  </joint>

  <link name="L7">
      <contact>
        <stiffness value="30000"/>
        <damping value="10000"/>        
        <lateral_friction value="0.1"/>
      </contact>
      <visual> 
          <geometry> 
              <cylinder length="0.0762" radius="0.082"/>
          </geometry>
          <origin rpy="1.57075 0 0"/>
          <material name="White"/>
      </visual>
      <collision> 
            <geometry> 
              <cylinder length="0.0762" radius="0.082"/>
          </geometry>
          <origin rpy="1.57075 0 0"/>
      </collision> 
      <inertial> 
          <origin rpy="1.57075 0 0"/>
          <mass value="0.12455"/>
          <inertia ixx="0.0002693" ixy="0" ixz="0" iyy="0.0002693" iyz="0" izz="0.0004187"/>
      </inertial> 
  </link> 

  <joint name="base_to_L8_wheel" type="continuous">
        <parent link="base_link"/>
        <child link="L8"/> 
        <axis xyz="0 1 0"/>
        <origin xyz="0.1042 -0.1721 0.0125"/>
  </joint>

  <link name="L8">
      <contact>
        <stiffness value="30000"/>
        <damping value="10000"/>        
        <lateral_friction value="0.1"/>
      </contact>
      <visual> 
          <geometry> 
              <cylinder length="0.0762" radius="0.082"/>
          </geometry>
          <origin rpy="1.57075 0 0"/>
          <material name="White"/>
      </visual>
      <collision> 
            <geometry> 
              <cylinder length="0.0762" radius="0.082"/>
          </geometry>
          <origin rpy="1.57075 0 0"/>
      </collision> 
      <inertial> 
          <origin rpy="1.57075 0 0"/>
          <mass value="0.12455"/>
          <inertia ixx="0.0002693" ixy="0" ixz="0" iyy="0.0002693" iyz="0" izz="0.0004187"/>
      </inertial> 
  </link> 

  <joint name="base_to_L9_wheel" type="continuous">
        <parent link="base_link"/>
        <child link="L9"/> 
        <axis xyz="0 1 0"/>
        <origin xyz="0.1563 -0.1721 0.0125"/>
  </joint>

  <link name="L9">
      <contact>
        <stiffness value="30000"/>
        <damping value="10000"/>        
        <lateral_friction value="0.1"/>
      </contact>
      <visual> 
          <geometry> 
              <cylinder length="0.0762" radius="0.082"/>
          </geometry>
          <origin rpy="1.57075 0 0"/>
          <material name="White"/>
      </visual>
      <collision> 
            <geometry> 
              <cylinder length="0.0762" radius="0.082"/>
          </geometry>
          <origin rpy="1.57075 0 0"/>
      </collision> 
      <inertial> 
          <origin rpy="1.57075 0 0"/>
          <mass value="0.12455"/>
          <inertia ixx="0.0002693" ixy="0" ixz="0" iyy="0.0002693" iyz="0" izz="0.0004187"/>
      </inertial> 
  </link> 

  <joint name="base_to_L10_wheel" type="continuous">
        <parent link="base_link"/>
        <child link="L10"/> 
        <axis xyz="0 1 0"/>
        <origin xyz="0.2084 -0.1721 0.0125"/>
  </joint>

  <link name="L10">
      <contact>
        <stiffness value="30000"/>
        <damping value="10000"/>        
        <lateral_friction value="0.1"/>
      </contact>
      <visual> 
          <geometry> 
              <cylinder length="0.0762" radius="0.082"/>
          </geometry>
          <origin rpy="1.57075 0 0"/>
          <material name="White"/>
      </visual>
      <collision> 
            <geometry> 
              <cylinder length="0.0762" radius="0.082"/>
          </geometry>
          <origin rpy="1.57075 0 0"/>
      </collision> 
      <inertial> 
          <origin rpy="1.57075 0 0"/>
          <mass value="0.12455"/>
          <inertia ixx="0.0002693" ixy="0" ixz="0" iyy="0.0002693" iyz="0" izz="0.0004187"/>
      </inertial> 
  </link> 

  <joint name="base_to_L11_wheel" type="continuous">
      <parent link="base_link"/>
      <child link="L11"/> 
      <axis xyz="0 1 0"/>
      <!-- Add 1/2 wheel thickness + 7 mm for the y offset-->
      <!-- Add the (685 mm) track length/2 - wheel radius for the maximal x offset-->
      <!-- Subtract the position of the wheel base above ground (39.5 mm) from wheel radius for the z offset-->
      <origin xyz="0.2605 -0.1721 0.0125"/>
  </joint>

  <link name="L11">
      <contact>
        <stiffness value="30000"/>
        <damping value="10000"/>        
        <lateral_friction value="0.1"/>
      </contact>
      <visual> 
          <geometry> 
              <cylinder length="0.0762" radius="0.082"/>
          </geometry>
          <origin rpy="1.57075 0 0"/>
          <material name="White"/>
      </visual>
      <collision> 
            <geometry> 
              <cylinder length="0.0762" radius="0.082"/>
          </geometry>
          <origin rpy="1.57075 0 0"/>
      </collision> 
      <inertial> 
          <origin rpy="1.57075 0 0"/>
          <mass value="0.12455"/>
          <inertia ixx="0.0002693" ixy="0" ixz="0" iyy="0.0002693" iyz="0" izz="0.0004187"/>
      </inertial> 
  </link> 
  
  <!-- Right Track -->

  <joint name="base_to_R1_wheel" type="continuous">
        <parent link="base_link"/>
        <child link="R1"/> 
        <axis xyz="0 1 0"/>
        <!-- Add 1/2 wheel thickness + 7 mm for the y offset-->
        <!-- Add the (685 mm) track length/2 - wheel radius for the maximal x offset-->
        <!-- Subtract the position of the wheel base above ground (39.5 mm) from wheel radius for the z offset-->
        <origin xyz="-0.2605 0.1721 0.0125"/>
  </joint>

  <link name="R1">
      <contact>
        <stiffness value="30000"/>
        <damping value="10000"/>        
        <lateral_friction value="0.1"/>
      </contact>
      <visual> 
          <geometry> 
              <cylinder length="0.0762" radius="0.082"/>
          </geometry>
          <origin rpy="1.57075 0 0"/>
          <material name="White"/>
      </visual>
      <collision> 
            <geometry> 
              <cylinder length="0.0762" radius="0.082"/>
          </geometry>
          <origin rpy="1.57075 0 0"/>
      </collision> 
      <inertial> 
          <origin rpy="1.57075 0 0"/>
          <mass value="0.12455"/>
          <inertia ixx="0.0002693" ixy="0" ixz="0" iyy="0.0002693" iyz="0" izz="0.0004187"/>
      </inertial> 
  </link>
  
  <joint name="base_to_R2_wheel" type="continuous">
        <parent link="base_link"/>
        <child link="R2"/> 
        <axis xyz="0 1 0"/>
        <origin xyz="-0.2084 0.1721 0.0125"/>
  </joint>

  <link name="R2">
      <contact>
        <stiffness value="30000"/>
        <damping value="10000"/>        
        <lateral_friction value="0.1"/>
      </contact>

      <visual> 
          <geometry> 
              <cylinder length="0.0762" radius="0.082"/>
          </geometry>
          <origin rpy="1.57075 0 0"/>
          <material name="White"/>
      </visual>
      <collision> 
            <geometry> 
              <cylinder length="0.0762" radius="0.082"/>
          </geometry>
          <origin rpy="1.57075 0 0"/>
      </collision> 
      <inertial> 
          <origin rpy="1.57075 0 0"/>
          <mass value="0.12455"/>
          <inertia ixx="0.0002693" ixy="0" ixz="0" iyy="0.0002693" iyz="0" izz="0.0004187"/>
      </inertial> 
  </link> 

  <joint name="base_to_R3_wheel" type="continuous">
        <parent link="base_link"/>
        <child link="R3"/> 
        <axis xyz="0 1 0"/>
        <origin xyz="-0.1563 0.1721 0.0125"/>
  </joint>

  <link name="R3">
      <contact>
        <stiffness value="30000"/>
        <damping value="10000"/>        
        <lateral_friction value="0.1"/>
      </contact>
      <visual> 
          <geometry> 
              <cylinder length="0.0762" radius="0.082"/>
          </geometry>
          <origin rpy="1.57075 0 0"/>
          <material name="White"/>
      </visual>
      <collision> 
            <geometry> 
              <cylinder length="0.0762" radius="0.082"/>
          </geometry>
          <origin rpy="1.57075 0 0"/>
      </collision> 
      <inertial> 
          <origin rpy="1.57075 0 0"/>
          <mass value="0.12455"/>
          <inertia ixx="0.0002693" ixy="0" ixz="0" iyy="0.0002693" iyz="0" izz="0.0004187"/>
      </inertial> 
  </link> 
  
  <joint name="base_to_R4_wheel" type="continuous">
        <parent link="base_link"/>
        <child link="R4"/> 
        <axis xyz="0 1 0"/>
        <origin xyz="-0.1042 0.1721 0.0125"/>
  </joint>

  <link name="R4">
      <contact>
        <stiffness value="30000"/>
        <damping value="10000"/>        
        <lateral_friction value="0.1"/>
      </contact>
      <visual> 
          <geometry> 
              <cylinder length="0.0762" radius="0.082"/>
          </geometry>
          <origin rpy="1.57075 0 0"/>
          <material name="White"/>
      </visual>
      <collision> 
            <geometry> 
              <cylinder length="0.0762" radius="0.082"/>
          </geometry>
          <origin rpy="1.57075 0 0"/>
      </collision> 
      <inertial> 
          <origin rpy="1.57075 0 0"/>
          <mass value="0.12455"/>
          <inertia ixx="0.0002693" ixy="0" ixz="0" iyy="0.0002693" iyz="0" izz="0.0004187"/>
      </inertial> 
  </link> 

  <joint name="base_to_R5_wheel" type="continuous">
        <parent link="base_link"/>
        <child link="R5"/> 
        <axis xyz="0 1 0"/>
        <origin xyz="-0.0521 0.1721 0.0125"/>
  </joint>

  <link name="R5">
      <contact>
        <stiffness value="30000"/>
        <damping value="10000"/>        
        <lateral_friction value="0.1"/>
      </contact>
      <visual> 
          <geometry> 
              <cylinder length="0.0762" radius="0.082"/>
          </geometry>
          <origin rpy="1.57075 0 0"/>
          <material name="White"/>
      </visual>
      <collision> 
            <geometry> 
              <cylinder length="0.0762" radius="0.082"/>
          </geometry>
          <origin rpy="1.57075 0 0"/>
      </collision> 
      <inertial> 
          <origin rpy="1.57075 0 0"/>
          <mass value="0.12455"/>
          <inertia ixx="0.0002693" ixy="0" ixz="0" iyy="0.0002693" iyz="0" izz="0.0004187"/>
      </inertial> 
  </link> 

  <joint name="base_to_R6_wheel" type="continuous">
        <parent link="base_link"/>
        <child link="R6"/> 
        <axis xyz="0 1 0"/>
        <origin xyz="0 0.1721 0.0125"/>
  </joint>

  <link name="R6">
      <contact>
        <stiffness value="30000"/>
        <damping value="10000"/>        
        <lateral_friction value="0.1"/>
      </contact>
      <visual> 
          <geometry> 
              <cylinder length="0.0762" radius="0.082"/>
          </geometry>
          <origin rpy="1.57075 0 0"/>
          <material name="White"/>
      </visual>
      <collision> 
            <geometry> 
              <cylinder length="0.0762" radius="0.082"/>
          </geometry>
          <origin rpy="1.57075 0 0"/>
      </collision> 
      <inertial> 
          <origin rpy="1.57075 0 0"/>
          <mass value="0.12455"/>
          <inertia ixx="0.0002693" ixy="0" ixz="0" iyy="0.0002693" iyz="0" izz="0.0004187"/>
      </inertial> 
  </link> 

  <joint name="base_to_R7_wheel" type="continuous">
        <parent link="base_link"/>
        <child link="R7"/> 
        <axis xyz="0 1 0"/>
        <origin xyz="0.0521 0.1721 0.0125"/>
  </joint>

  <link name="R7">
      <contact>
        <stiffness value="30000"/>
        <damping value="10000"/>        
        <lateral_friction value="0.1"/>
      </contact>
      <visual> 
          <geometry> 
              <cylinder length="0.0762" radius="0.082"/>
          </geometry>
          <origin rpy="1.57075 0 0"/>
          <material name="White"/>
      </visual>
      <collision> 
            <geometry> 
              <cylinder length="0.0762" radius="0.082"/>
          </geometry>
          <origin rpy="1.57075 0 0"/>
      </collision> 
      <inertial> 
          <origin rpy="1.57075 0 0"/>
          <mass value="0.12455"/>
          <inertia ixx="0.0002693" ixy="0" ixz="0" iyy="0.0002693" iyz="0" izz="0.0004187"/>
      </inertial> 
  </link> 

  <joint name="base_to_R8_wheel" type="continuous">
        <parent link="base_link"/>
        <child link="R8"/> 
        <axis xyz="0 1 0"/>
        <origin xyz="0.1042 0.1721 0.0125"/>
  </joint>

  <link name="R8">
      <contact>
        <stiffness value="30000"/>
        <damping value="10000"/>        
        <lateral_friction value="0.1"/>
      </contact>
      <visual> 
          <geometry> 
              <cylinder length="0.0762" radius="0.082"/>
          </geometry>
          <origin rpy="1.57075 0 0"/>
          <material name="White"/>
      </visual>
      <collision> 
            <geometry> 
              <cylinder length="0.0762" radius="0.082"/>
          </geometry>
          <origin rpy="1.57075 0 0"/>
      </collision> 
      <inertial> 
          <origin rpy="1.57075 0 0"/>
          <mass value="0.12455"/>
          <inertia ixx="0.0002693" ixy="0" ixz="0" iyy="0.0002693" iyz="0" izz="0.0004187"/>
      </inertial> 
  </link> 

  <joint name="base_to_R9_wheel" type="continuous">
        <parent link="base_link"/>
        <child link="R9"/> 
        <axis xyz="0 1 0"/>
        <origin xyz="0.1563 0.1721 0.0125"/>
  </joint>

  <link name="R9">
     <contact>
        <stiffness value="30000"/>
        <damping value="10000"/>        
        <lateral_friction value="0.1"/>
      </contact>
      <visual> 
          <geometry> 
              <cylinder length="0.0762" radius="0.082"/>
          </geometry>
          <origin rpy="1.57075 0 0"/>
          <material name="White"/>
      </visual>
      <collision> 
            <geometry> 
              <cylinder length="0.0762" radius="0.082"/>
          </geometry>
          <origin rpy="1.57075 0 0"/>
      </collision> 
      <inertial> 
          <origin rpy="1.57075 0 0"/>
          <mass value="0.12455"/>
          <inertia ixx="0.0002693" ixy="0" ixz="0" iyy="0.0002693" iyz="0" izz="0.0004187"/>
      </inertial> 
  </link> 0.05

  <joint name="base_to_R10_wheel" type="continuous">
        <parent link="base_link"/>
        <child link="R10"/> 
        <axis xyz="0 1 0"/>
        <origin xyz="0.2084 0.1721 0.0125"/>
  </joint>

  <link name="R10">
      <contact>
        <stiffness value="30000"/>
        <damping value="10000"/>        
        <lateral_friction value="0.1"/>
      </contact>
      <visual> 
          <geometry> 
              <cylinder length="0.0762" radius="0.082"/>
          </geometry>
          <origin rpy="1.57075 0 0"/>
          <material name="White"/>
      </visual>
      <collision> 
            <geometry> 
              <cylinder length="0.0762" radius="0.082"/>
          </geometry>
          <origin rpy="1.57075 0 0"/>
      </collision> 
      <inertial> 
          <origin rpy="1.57075 0 0"/>
          <mass value="0.12455"/>
          <inertia ixx="0.0002693" ixy="0" ixz="0" iyy="0.0002693" iyz="0" izz="0.0004187"/>
      </inertial> 
  </link> 

  <joint name="base_to_R11_wheel" type="continuous">
      <parent link="base_link"/>
      <child link="R11"/> 
      <axis xyz="0 1 0"/>
      <!-- Add 1/2 wheel thickness + 7 mm for the y offset-->
      <!-- Add the (685 mm) track length/2 - wheel radius for the maximal x offset-->
      <!-- Subtract the position of the wheel base above ground (39.5 mm) from wheel radius for the z offset-->
      <origin xyz="0.2605 0.1721 0.0125"/>
  </joint>

  <link name="R11">
      <contact>
        <stiffness value="30000"/>
        <damping value="10000"/>        
        <lateral_friction value="0.1"/>
      </contact>
      <visual> 
          <geometry> 
              <cylinder length="0.0762" radius="0.082"/>
          </geometry>
          <origin rpy="1.57075 0 0"/>
          <material name="White"/>
      </visual>
      <collision> 
            <geometry> 
              <cylinder length="0.0762" radius="0.082"/>
          </geometry>
          <origin rpy="1.57075 0 0"/>
      </collision> 
      <inertial> 
          <origin rpy="1.57075 0 0"/>
          <mass value="0.12455"/>
          <inertia ixx="0.0002693" ixy="0" ixz="0" iyy="0.0002693" iyz="0" izz="0.0004187"/>
      </inertial> 
  </link> 
    
  <!-- FLIPPERS -->

  <!-- FRONT LEFT FLIPPER-->

  <joint name="base_to_flippers" type="continuous">
    <parent link="base_link"/>
    <child link="LF_flipper_main"/>
    <!--<limit effort="1.0" velocity="4"/>-->
    <!--Add the wheel thickness and the half width of the flipper and 7 mm to get the y offset-->
    <origin rpy="0 -3.14 0" xyz="0.2605 -0.2418 0.0125"/>
    <axis xyz="0 1 0"/>
    <dynamics damping="0.0"/>
  </joint>

  <link name="LF_flipper_main">
    <contact>
      <damping value="11000"/>
      <stiffness value="32000"/>
      <lateral_friction value="0.8"/>
    </contact>
    <visual>
      <geometry>
        <mesh filename="flipper.stl" scale="0.001 0.001 0.001"/>
      </geometry>
      <origin rpy="0 0 1.57075" xyz="0 0 0"/>
      <material name="Blue" />
    </visual>
    <collision>
      <geometry>
        <mesh filename="flipper.stl" scale="0.001 0.001 0.001"/>
      </geometry>
      <origin rpy="0 0 1.57075" xyz="0 0 0"/>
    </collision>
    <inertial>
        <mass value="1.026" />
        <origin rpy="0 0 0" xyz="0.03 0 0 " />
        <inertia ixx="0.000926" ixy="0" ixz="0" iyy="0.001459" iyz="0" izz="0.00825" />
      </inertial>
  </link>
 
  <!-- FRONT RIGHT FLIPPER-->

  <joint name="LF_to_RF_flipper" type="fixed">
      <parent link="LF_flipper_main"/>
      <child link="RF_flipper_main"/>
      <!--<limit effort="1.0" velocity="4"/>-->
      <origin xyz="0 0.4836 0"/>
      <axis xyz="0 1 0"/>
      <dynamics damping="0.0"/>
  </joint>

  <link name="RF_flipper_main">
    <contact>
      <damping value="11000"/>
      <stiffness value="32000"/>
      <lateral_friction value="0.8"/>
    </contact>
    <visual>
      <geometry>
        <mesh filename="flipper.stl" scale="0.001 0.001 0.001"/>
      </geometry>
      <origin rpy="0 0 1.57075" xyz="0 0 0"/>
      <material name="Blue" />
    </visual>
    <collision>
      <geometry>
        <mesh filename="flipper.stl" scale="0.001 0.001 0.001"/>
      </geometry>
      <origin rpy="0 0 1.57075" xyz="0 0 0"/>
    </collision>
    <inertial>
        <mass value="1.026" />
        <origin rpy="0 0 0" xyz="0.03 0 0" />
        <inertia ixx="0.000926" ixy="0" ixz="0" iyy="0.001459" iyz="0" izz="0.00825" />
      </inertial>
  </link>

  <!-- PAYLOAD FRAME-->
  
  <joint name="base_to_1010_base" type="fixed">
      <parent link="base_link"/>
      <child link="1010_base"/>
      <origin xyz="-0.2973 0 0.12"/>
  </joint>

  <link name="1010_base">
    <visual>
      <origin rpy="1.57075 0 0" xyz="0 0 0"/>
      <geometry>
        <box size="0.0254 0.0254 0.430"/>
      </geometry>
      <material name="Black"/>
    </visual>

    <inertial>
      <!-- CENTER OF MASS -->
      <origin rpy="1.57075 0 0" xyz="0 0 0"/>
      <mass value="0.325"/>
      <!-- moments of inertia around the COM in the output frame of reference --> 
      <!-- must negate the products of inertia from CAD output (see wiki.ros.org/urdf/XML/link for details)-->
      <inertia ixx="0.005" ixy="0" ixz="0.0" iyy="0.005" iyz="0.0" izz="0.000035"/>
    </inertial>
  </link>

  <joint name="base_to_1020_base" type="fixed">
      <parent link="base_link"/>
      <child link="1020_base"/>
      <origin xyz="0.248 0 0.12"/>
  </joint>

  <link name="1020_base">
    <visual>
      <origin rpy="1.57075 0 0" xyz="0 0 0"/>
      <geometry>
        <box size="0.0508 0.0254 0.430"/>
      </geometry>
      <material name="Black"/>
    </visual>

    <inertial>
      <!-- CENTER OF MASS -->
      <origin rpy="1.57075 0 0" xyz="0 0 0"/>
      <mass value="0.589"/>
      <!-- moments of inertia around the COM in the output frame of reference --> 
      <!-- must negate the products of inertia from CAD output (see wiki.ros.org/urdf/XML/link for details)-->
      <inertia ixx="0.00921" ixy="0" ixz="0.0" iyy="0.00912" iyz="0.0" izz="0.000158"/>
    </inertial>
  </link>

  <joint name="1020_base_to_front_staff" type="fixed">
      <parent link="1020_base"/>
      <child link="front_staff"/>
      <origin xyz="0 0 0.5207"/>
  </joint>

  <link name="front_staff">
    <visual>
      <origin rpy="0 0 0" xyz="0 0 0"/>
      <geometry>
        <box size="0.0508 0.0254 1.016"/>
      </geometry>
      <material name="Black"/>
    </visual>

    <inertial>
      <!-- CENTER OF MASS -->
      <origin rpy="0 0 0" xyz="0 0 0"/>
      <mass value="1.3937"/>
      <!-- moments of inertia around the COM in the output frame of reference --> 
      <!-- must negate the products of inertia from CAD output (see wiki.ros.org/urdf/XML/link for details)-->
      <inertia ixx="0.1199" ixy="0" ixz="0.0" iyy="0.1201" iyz="0.0" izz="0.000374"/>
    </inertial>
  </link>

  <joint name="1010_base_to_little_piece" type="fixed">
      <parent link="1010_base"/>
      <child link="little_piece"/>
      <origin xyz="0 0 0.0635"/>
  </joint>

  <link name="little_piece">
    <visual>
      <origin rpy="0 0 0" xyz="0 0 0"/>
      <geometry>
        <box size="0.0254 0.0254 0.1016"/>
      </geometry>
      <material name="Black"/>
    </visual>

    <inertial>
      <!-- CENTER OF MASS -->
      <origin rpy="0 0 0" xyz="0 0 0"/>
      <mass value="0.0769"/>
      <!-- moments of inertia around the COM in the output frame of reference --> 
      <!-- must negate the products of inertia from CAD output (see wiki.ros.org/urdf/XML/link for details)-->
      <inertia ixx="0.00000703" ixy="0" ixz="0.0" iyy="0.00000703" iyz="0.0" izz="0.000000827"/>
    </inertial>
  </link>

  <joint name="front_staff_to_bottom_bar" type="fixed">
      <parent link="front_staff"/>
      <child link="bottom_bar"/>
      <origin xyz="-0.4761 0 -0.4064"/>
  </joint>

  <link name="bottom_bar">
    <visual>
      <origin rpy="0 1.57075 0" xyz="0 0 0"/>
      <geometry>
        <box size="0.0254 0.0254 0.914"/>
      </geometry>
      <material name="Black"/>
    </visual>

    <inertial>
      <!-- CENTER OF MASS -->
      <origin rpy="0 0 0" xyz="0 0 0"/>
      <mass value="0.692"/>
      <!-- moments of inertia around the COM in the output frame of reference --> 
      <!-- must negate the products of inertia from CAD output (see wiki.ros.org/urdf/XML/link for details)-->
      <inertia ixx="0.0482" ixy="0" ixz="0.0" iyy="0.0482" iyz="0.0" izz="0.0000744"/>
    </inertial>
  </link>

  <joint name="bottom_bar_to_back_staff" type="fixed">
      <parent link="bottom_bar"/>
      <child link="back_staff"/>
      <origin xyz="-0.3693 0 0.3937"/>
  </joint>

  <link name="back_staff">
    <visual>
      <origin rpy="0 0 0" xyz="0 0 0"/>
      <geometry>
        <box size="0.0254 0.0254 0.762"/>
      </geometry>
      <material name="Black"/>
    </visual>bottom_bar

    <inertial>
      <!-- CENTER OF MASS -->
      <origin rpy="0 0 0" xyz="0 0 0"/>
      <mass value="0.577"/>
      <!-- moments of inertia around the COM in the output frame of reference --> 
      <!-- must negate the products of inertia from CAD output (see wiki.ros.org/urdf/XML/link for details)-->
      <inertia ixx="0.02795" ixy="0" ixz="0.0" iyy="0.02795" iyz="0.0" izz="0.000062"/>
    </inertial>
  </link>

  <joint name="bottom_bar" type="fixed">
      <parent link="bottom_bar"/>
      <child link="top_bar"/>
      <origin xyz="0 0 0.7854"/>
  </joint>

  <link name="top_bar">
    <visual>
      <origin rpy="0 1.57075 0" xyz="0 0 0"/>
      <geometry>
        <box size="0.0254 0.0254 0.914"/>
      </geometry>
      <material name="Black"/>
    </visual>

    <inertial>
      <!-- CENTER OF MASS -->
      <origin rpy="0 0 0" xyz="0 0 0"/>
      <mass value="0.692"/>
      <!-- moments of inertia around the COM in the output frame of reference --> 
      <!-- must negate the products of inertia from CAD output (see wiki.ros.org/urdf/XML/link for details)-->
      <inertia ixx="0.0482" ixy="0" ixz="0.0" iyy="0.0482" iyz="0.0" izz="0.0000744"/>
    </inertial>
  </link>
  
  <!-- PAYLOAD_PLACEHOLDER -->
 
</robot>
